Workbook

Sheet Reference
A1: Food item code in Household Survey (item_cod) | B1: Average edible quantity (g/capita/day) | C1: Food item description in Household Survey (desc) | D1: SA Table Code | E1: SA Table Name | F1: Reference Food Composition Table (FCT) | G1: Food code in FCT | H1: Food description in FCT | I1: Food Item Index Matching (Read the text in the comment of this cell) | J1: Refuse factor (refuse) | K1: Item Group (item_grp) | L1: Item Group (diversity_grp) | M1: Water (grams) | N1: Ash (grams) | O1: Protein (grams) (fd_pro) | P1: Total Fat (grams) (fd_fat) | Q1: Total Fiber (grams) (fd_fib) | R1: Alcohol (grams) (fd_alc) | S1: Carbohydrates including fiber (Total) (grams) | T1: Available Carbohydrates by difference (grams) (fd_car) | U1: Calories (Kcal) | V1: Computed calories (Kcal) (fd_kcal) | W1: Calcium (milligrams) (calcium) | X1: Iron (milligrams) (iron) | Y1: Animal iron (milligrams) (fe_anim) | Z1: Non animal iron (milligrams) (fe_nanim) | AA1: Haem iron (milligrams) (fe_haem) | AB1: Non-haem iron (milligrams) (fe_nhaem) | AC1: Zinc (milligrams) zinc | AD1: Folate (micrograms) folate | AE1: Vitamin C (Ascorbic Acid) (milligrams) (vit_c) | AF1: Vitamin B1 (Thiamine) (milligrams) (vit_b1) | AG1: Vitamin B2 (Riboflavin) (milligrams) (vit_b2) | AH1: Retinol (micrograms) (retinol) | AI1: Betacarotene equivalents (micrograms) (betacar) | AJ1: Vitamin A (micrograms of RAE o RE) (vita) | AK1: Vitamin B6 (Pyridoxine) (milligrams) (vit_b6) | AL1: Vitamin B12 (Cobalamine) (micrograms) (vit_b12) | AM1: Isoleucine (grams) (isoleuc) | AN1: Leucine (grams) (leucine) | AO1: Lysine (grams) (lysine) | AP1: Methionine (grams) (methion) | AQ1: Phenylalanine (grams) (phenyl) | AR1: Threonine (grams) (threon) | AS1: Tryptophan (grams) (trypto) | AT1: Valine (grams) (valine) | AU1: Histidine (grams) (histid) | AV1: Cystine (grams) (cysteine) | AW1: Tyrosine (grams) (tyrosine)
A2: 1112.01 | B2: =VLOOKUP(A2,'Table 3.1'!$A$4:$D$186,4,FALSE) -> 168.44418 | C2: Bread (white, brown, whole wheat, rye, maize, etc.) | D2: 3210 | E2: Bread/Rolls, white (fortified) | F2: WA_FCT | G2: 01_046 | H2: Bread, wheat, white | J2: 0 | W2: 28 | X2: 1.2 | Y2: 0 | Z2: 1.2 | AC2: 0.6 | AD2: 29 | AE2: 0 | AF2: 0.16 | AG2: 0.05 | AH2: 0 | AI2: 0 | AJ2: 0 | AK2: 0.06 | AL2: 0
A3: 1115.04 | B3: =VLOOKUP(A3,'Table 3.1'!$A$4:$D$186,4,FALSE) -> 131.59491 | C3: Maize meal/ grain/ samp | D3: 4409 | E3: Maize meal, sifted, raw (white, fortified) | F3: WA_FCT | G3: 01_014 | H3: Maize, combined varieties, whole kernel, dried, raw (Benin) | J3: 0 | W3: 18 | X3: 3 | Y3: 0 | Z3: 3 | AC3: 1.51 | AD3: 25 | AE3: 0 | AF3: 0.34 | AG3: 0.1 | AH3: 0 | AI3: 0 | AJ3: 0 | AK3: 0.2 | AL3: 0
A4: 1223.02 | B4: =VLOOKUP(A4,'Table 3.1'!$A$4:$D$186,4,FALSE) -> 112.25229 | C4: Mageu/Oshikundu | D4: 4410 | E4: Maize meal, super, porridge, soft (white, fortified) | F4: WA_FCT | G4: 01_061 | H4: Maize, white, soft porridge* (without salt) | I4: B2 | J4: 0 | W4: 1 | X4: 0.04 | Y4: 0 | Z4: 0.04 | AC4: 0.06 | AD4: 1 | AE4: 0 | AF4: 0.01 | AG4: 0.02 | AH4: 0 | AI4: 0 | AJ4: 0 | AK4: 0.01 | AL4: 0
A5: 1121.01 | B5: =VLOOKUP(A5,'Table 3.1'!$A$4:$D$186,4,FALSE) -> 93.177287 | C5: Beef | F5: WA_FCT | G5: 07_005 | H5: Average beef from average tabs | J5: 0 | W5: 11 | X5: 1.8 | Y5: 1.8 | Z5: 0 | AC5: 3.6 | AD5: 3 | AE5: 0 | AF5: 0.6 | AG5: 0.17 | AH5: 0 | AI5: 0 | AJ5: 0 | AK5: 0.38 | AL5: 0.7
A6: 1115.05 | B6: =VLOOKUP(A6,'Table 3.1'!$A$4:$D$186,4,FALSE) -> 77.931404 | C6: Mahangu meal/ grain/ samp | F6: WA_FCT | G6: 01_017 | H6: Pearl millet, whole grain, raw (with bran) | J6: 0 | W6: 14 | X6: 7.6 | Y6: 0 | Z6: 7.6 | AC6: 2.83 | AD6: 30 | AE6: 0 | AF6: 0.32 | AG6: 0.27 | AH6: 0 | AI6: 3 | AJ6: 0 | AK6: 0.74 | AL6: 0
A7: 1111.01 | B7: =VLOOKUP(A7,'Table 3.1'!$A$4:$D$186,4,FALSE) -> 22.321716 | C7: Rice | F7: WA_FCT | G7: 01_037 | H7: Rice, white, raw | J7: 0 | W7: 12 | X7: 1.4 | Y7: 0 | Z7: 1.4 | AC7: 1.16 | AD7: 20 | AE7: 0 | AF7: 0.07 | AG7: 0.04 | AH7: 0 | AI7: 0 | AJ7: 0 | AK7: 0.2 | AL7: 0
A8: 1212.01 | B8: =VLOOKUP(A8,'Table 3.1'!$A$4:$D$186,4,FALSE) -> 20.632186 | C8: Tea | F8: WA_FCT | G8: 12_008 | H8: GOLD PEAK TEA, ICED TEA, SWEET TEA | I8: A | J8: 0 | W8: 7 | X8: 0.2 | Y8: 0 | Z8: 0.2 | AC8: 0.08 | AD8: 14 | AE8: 40.6 | AF8: 0.03 | AG8: 0.01 | AH8: 0 | AI8: 7 | AJ8: 1 | AK8: 0.05 | AL8: 0
A9: 1222.01 | B9: =VLOOKUP(A9,'Table 3.1'!$A$4:$D$186,4,FALSE) -> 20.183571 | C9: Soft drinks | F9: WA_FCT | G9: 12_011 | H9: Juice, orange, unsweetened | I9: A | J9: 0 | W9: 12 | X9: 0.3 | Y9: 0 | Z9: 0.3 | AC9: 0.05 | AD9: 34 | AE9: 42.7 | AF9: 0.08 | AG9: 0.03 | AH9: 0 | AI9: 100 | AJ9: 8 | AK9: 0.06 | AL9: 0
A10: 1144.03 | B10: =VLOOKUP(A10,'Table 3.1'!$A$4:$D$186,4,FALSE) -> 18.175392 | C10: Traditional sour milk | F10: WA_FCT | G10: 10_013 | H10: Milk, cow, whole, 3.5 % fat (includes pasteurised, sterilised and UHT) | I10: A2 | J10: 0 | W10: 122 | X10: 0.03 | Y10: 0.03 | Z10: 0 | AC10: 0.41 | AD10: 12 | AE10: 1.3 | AF10: 0.05 | AG10: 0.18 | AH10: 13 | AI10: 7 | AJ10: 14 | AK10: 0.05 | AL10: 0.5
A11: 1113.01 | B11: =VLOOKUP(A11,'Table 3.1'!$A$4:$D$186,4,FALSE) -> 15.198223 | C11: Macaroni, spaghetti, noodles | D11: 3262 | E11: Macaroni/Spaghetti, cooked | F11: WA_FCT | G11: 01_053 | H11: Macaroni, boiled* (without salt) | J11: 0 | W11: 10 | X11: 0.5 | Y11: 0 | Z11: 0.5 | AC11: 0.59 | AD11: 5 | AE11: 0 | AF11: 0.05 | AG11: 0.01 | AH11: 0 | AI11: 0 | AJ11: 0 | AK11: 0.03 | AL11: 0
A12: 1177.01 | B12: =VLOOKUP(A12,'Table 3.1'!$A$4:$D$186,4,FALSE) -> 14.014303 | C12: Potatoes, English | F12: WA_FCT | G12: 02_009 | H12: Potato, raw | J12: 0.16 | W12: 11 | X12: 0.9 | Y12: 0 | Z12: 0.9 | AC12: 0.35 | AD12: 18 | AE12: 17.3 | AF12: 0.08 | AG12: 0.12 | AH12: 0 | AI12: 14 | AJ12: 1 | AK12: 0.27 | AL12: 0
A13: 1223.01 | B13: =VLOOKUP(A13,'Table 3.1'!$A$4:$D$186,4,FALSE) -> 13.384258 | C13: Fruit juice & squashes | F13: WA_FCT | G13: 12_011 | H13: Juice, orange, unsweetened | I13: A | J13: 0 | W13: 12 | X13: 0.3 | Y13: 0 | Z13: 0.3 | AC13: 0.05 | AD13: 34 | AE13: 42.7 | AF13: 0.08 | AG13: 0.03 | AH13: 0 | AI13: 100 | AJ13: 8 | AK13: 0.06 | AL13: 0
A14: 1141.01 | B14: =VLOOKUP(A14,'Table 3.1'!$A$4:$D$186,4,FALSE) -> 13.116385 | C14: Fresh milk | F14: WA_FCT | G14: 10_001 | H14: Milk, cow, whole, 3.5 % fat (includes pasteurised, sterilised and UHT) | J14: 0 | W14: 120 | X14: 0.05 | Y14: 0.05 | Z14: 0 | AC14: 0.39 | AD14: 10 | AE14: 1.5 | AF14: 0.04 | AG14: 0.18 | AH14: 31 | AI14: 18 | AJ14: 33 | AK14: 0.05 | AL14: 0.6
A15: 1171.02 | B15: =VLOOKUP(A15,'Table 3.1'!$A$4:$D$186,4,FALSE) -> 12.963092 | C15: Spinach/ Ombindi/ Derere/ Mutete/ Ekaka | F15: WA_FCT | G15: 04_057 | H15: Spinach, raw | J15: 0.28 | W15: 133 | X15: 3.1 | Y15: 0 | Z15: 3.1 | AC15: 0.8 | AD15: 176 | AE15: 36 | AF15: 0.08 | AG15: 0.17 | AH15: 0 | AI15: 6040 | AJ15: 409 | AK15: 0.19 | AL15: 0
A16: 1115.01 | B16: =VLOOKUP(A16,'Table 3.1'!$A$4:$D$186,4,FALSE) -> 10.421325 | C16: Breakfast cereals (all types) | F16: USDA_FCT | G16: 8023 | H16: CEREALS RTE,KELLOGG,KELLOGG'S CRACKLIN' OAT BRAN | J16: 0 | W16: 60 | X16: 3.7 | Y16: 0 | Z16: 3.7 | AC16: 3.1 | AD16: 204 | AE16: 31 | AF16: 0.8 | AG16: 0.9 | AH16: 459 | AI16: 0 | AJ16: 459 | AK16: 1 | AL16: 3.1
A17: 1131.01 | B17: =VLOOKUP(A17,'Table 3.1'!$A$4:$D$186,4,FALSE) -> 9.8993105 | C17: Fresh fish | F17: WA_FCT | G17: 09_041 | H17: Tilapia, raw | J17: 0.45 | W17: 17 | X17: 1.3 | Y17: 1.3 | Z17: 0 | AC17: 0.83 | AD17: 24 | AE17: 0 | AF17: 0.04 | AG17: 0.06 | AH17: 26 | AI17: 0 | AJ17: 26 | AK17: 0.24 | AL17: 1.6
A18: 1123.01 | B18: =VLOOKUP(A18,'Table 3.1'!$A$4:$D$186,4,FALSE) -> 9.0875713 | C18: Goat meat | F18: WA_FCT | G18: 07_046 | H18: Goat, meat, raw | J18: 0.26 | W18: 11 | X18: 2.4 | Y18: 2.4 | Z18: 0 | AC18: 3.45 | AD18: 5 | AE18: 0 | AF18: 0.18 | AG18: 0.29 | AH18: 0 | AI18: 0 | AJ18: 0 | AK18: 0.4 | AL18: 1.1
A19: 1181.01 | B19: =VLOOKUP(A19,'Table 3.1'!$A$4:$D$186,4,FALSE) -> 9.0340987 | C19: Sugar | F19: WA_FCT | G19: 13_002 | H19: Sugar | J19: 0 | W19: 1 | X19: 0.1 | Y19: 0 | Z19: 0.1 | AC19: 0.01 | AD19: 0 | AE19: 0 | AF19: 0 | AG19: 0.02 | AH19: 0 | AI19: 0 | AJ19: 0 | AK19: 0 | AL19: 0
A20: 1131.02 | B20: =VLOOKUP(A20,'Table 3.1'!$A$4:$D$186,4,FALSE) -> 8.9867299 | C20: Frozen fish | F20: WA_FCT | G20: 09_003 | H20: Mackerel, raw | J20: 0.29 | W20: 28 | X20: 0.8 | Y20: 0.8 | Z20: 0 | AC20: 0.49 | AD20: 1 | AE20: 0 | AF20: 0.14 | AG20: 0.14 | AH20: 39 | AI20: 0 | AJ20: 39 | AK20: 0.4 | AL20: 2.4
A21: 1195.99 | B21: =VLOOKUP(A21,'Table 3.1'!$A$4:$D$186,4,FALSE) -> 8.9556331 | C21: Other foods (specify) | F21: USDA_FCT | G21: 6147 | H21: SOUP,BF MUSHROOM,CND,COND | J21: 0 | W21: 4 | X21: 0.7 | Y21: 0 | Z21: 0.7 | AC21: 1.1 | AD21: 7 | AE21: 0 | AF21: 0.02 | AG21: 0.06 | AH21: 0 | AI21: 0 | AJ21: 0 | AK21: 0.04 | AL21: 0.16
A22: 1154.01 | B22: =VLOOKUP(A22,'Table 3.1'!$A$4:$D$186,4,FALSE) -> 7.2011585 | C22: Cooking oil | D22: 3486 | E22: Vegetable oil (50% sunflower,30% maize, 20% peanut) | F22: WA_FCT | G22: 11_010 | H22: Vegetable oil | J22: 0 | W22: 0 | X22: 0 | Y22: 0 | Z22: 0 | AC22: 0 | AD22: 0 | AE22: 0 | AF22: 0 | AG22: 0 | AH22: 0 | AI22: 0 | AJ22: 0 | AK22: 0 | AL22: 0
A23: 1173.09 | B23: =VLOOKUP(A23,'Table 3.1'!$A$4:$D$186,4,FALSE) -> 7.0995243 | C23: Tomatoes | F23: WA_FCT | G23: 04_021 | H23: Tomato, red, ripe, raw | J23: 0.09 | W23: 13 | X23: 0.6 | Y23: 0 | Z23: 0.6 | AC23: 0.7 | AD23: 21 | AE23: 29.6 | AF23: 0.06 | AG23: 0.04 | AH23: 0 | AI23: 624 | AJ23: 52 | AK23: 0.09 | AL23: 0
A24: 1167.02 | B24: =VLOOKUP(A24,'Table 3.1'!$A$4:$D$186,4,FALSE) -> 6.908326 | C24: Watermelons | F24: WA_FCT | G24: 05_038 | H24: Melon, honeydew, raw | J24: 0.54 | W24: 7 | X24: 0.3 | Y24: 0 | Z24: 0.3 | AC24: 0.09 | AD24: 12 | AE24: 14.2 | AF24: 0.03 | AG24: 0.01 | AH24: 0 | AI24: 31 | AJ24: 3 | AK24: 0.07 | AL24: 0
A25: 1174.06 | B25: =VLOOKUP(A25,'Table 3.1'!$A$4:$D$186,4,FALSE) -> 6.8998956 | C25: Onion | F25: WA_FCT | G25: 04_018 | H25: Onion, raw | J25: 0.09 | W25: 25 | X25: 0.3 | Y25: 0 | Z25: 0.3 | AC25: 0.26 | AD25: 16 | AE25: 10.3 | AF25: 0.05 | AG25: 0.04 | AH25: 0 | AI25: 1 | AJ25: 0 | AK25: 0.1 | AL25: 0
A26: 1123.02 | B26: =VLOOKUP(A26,'Table 3.1'!$A$4:$D$186,4,FALSE) -> 6.1624195 | C26: Mutton/ Lamb | F26: WA_FCT | G26: 07_049 | H26: Lamb/mutton, meat, moderately fat, boiled* (without salt) | J26: 0.25 | W26: 12 | X26: 3.1 | Y26: 3.1 | Z26: 0 | AC26: 4.97 | AD26: 2 | AE26: 0 | AF26: 0.08 | AG26: 0.15 | AH26: 12 | AI26: 0 | AJ26: 12 | AK26: 0.24 | AL26: 2.6
A27: 1173.08 | B27: =VLOOKUP(A27,'Table 3.1'!$A$4:$D$186,4,FALSE) -> 5.9821318 | C27: Pumpkins baby marrows & squashes, all types | F27: WA_FCT | G27: 04_051 | H27: Pumpkin, squash, raw | J27: 0.7 | W27: 19 | X27: 1.2 | Y27: 0 | Z27: 1.2 | AC27: 0.32 | AD27: 8 | AE27: 8 | AF27: 0.05 | AG27: 0.02 | AH27: 0 | AI27: 1200 | AJ27: 100 | AK27: 0.1 | AL27: 0
A28: 2131.01 | B28: =VLOOKUP(A28,'Table 3.1'!$A$4:$D$186,4,FALSE) -> 5.6051936 | C28: Beer/ Ales/ Ciders | F28: WA_FCT | G28: 12_001 | H28: Beer european (4.4 % alcohol) | J28: 0 | W28: 8 | X28: 0.1 | Y28: 0 | Z28: 0.1 | AC28: 0.01 | AD28: 5 | AE28: 0 | AF28: 0 | AG28: 0.03 | AH28: 0 | AI28: 0 | AJ28: 0 | AK28: 0.07 | AL28: 0
A29: 1122.01 | B29: =VLOOKUP(A29,'Table 3.1'!$A$4:$D$186,4,FALSE) -> 5.5779113 | C29: Pork | F29: WA_FCT | G29: 07_005 | H29: Pork, meat, approx. 40 % fat, boneless, raw | J29: 0 | W29: 11 | X29: 1.8 | Y29: 1.8 | Z29: 0 | AC29: 3.6 | AD29: 3 | AE29: 0 | AF29: 0.6 | AG29: 0.17 | AH29: 0 | AI29: 0 | AJ29: 0 | AK29: 0.38 | AL29: 0.7
A30: 2131.99 | B30: =VLOOKUP(A30,'Table 3.1'!$A$4:$D$186,4,FALSE) -> 4.9464179 | C30: Local home-made brew, all types (tombo, epwaka, shafuluka) | F30: WA_FCT | G30: 12_004 | H30: Beer, sorghum (est. 3% alcohol) | J30: 0 | W30: 8 | X30: 0.2 | Y30: 0 | Z30: 0.2 | AC30: 0.14 | AD30: 0 | AE30: 0 | AF30: 0.02 | AG30: 0.04 | AH30: 0 | AI30: 0 | AJ30: 0 | AK30: 0 | AL30: 0
A31: 1172.02 | B31: =VLOOKUP(A31,'Table 3.1'!$A$4:$D$186,4,FALSE) -> 4.5718787 | C31: Cabbage | F31: WA_FCT | G31: 04_005 | H31: Cabbage, raw | J31: 0.2 | W31: 41 | X31: 0.6 | Y31: 0 | Z31: 0.6 | AC31: 0.2 | AD31: 48 | AE31: 54 | AF31: 0.05 | AG31: 0.04 | AH31: 0 | AI31: 100 | AJ31: 8 | AK31: 0.1 | AL31: 0
A32: 1127.01 | B32: =VLOOKUP(A32,'Table 3.1'!$A$4:$D$186,4,FALSE) -> 4.2834915 | C32: Game/ Iguana | F32: USDA_FCT | G32: 17164 | H32: Game meat,Deer, raw | J32: 0 | W32: 5 | X32: 3.4 | Y32: 3.4 | Z32: 0 | AC32: 2.09 | AD32: 4 | AE32: 0 | AF32: 0.22 | AG32: 0.48 | AH32: 0 | AI32: 0 | AJ32: 0 | AK32: 0.37 | AL32: 6.31
A33: 1222.99 | B33: =VLOOKUP(A33,'Table 3.1'!$A$4:$D$186,4,FALSE) -> 4.160192 | C33: Other non-alcoholic drinks (Energade, Powerade) (specify) | F33: WA_FCT | G33: 12_011 | H33: Juice, orange, unsweetened | I33: A | J33: 0 | W33: 12 | X33: 0.3 | Y33: 0 | Z33: 0.3 | AC33: 0.05 | AD33: 34 | AE33: 42.7 | AF33: 0.08 | AG33: 0.03 | AH33: 0 | AI33: 100 | AJ33: 8 | AK33: 0.06 | AL33: 0
A34: 1112.09 | B34: =VLOOKUP(A34,'Table 3.1'!$A$4:$D$186,4,FALSE) -> 3.9007853 | C34: Traditional bread, ash bread, oshikwiila, oshima, omungome | D34: 3285 | E34: Bread/Rolls, white, high protein | F34: WA_FCT | G34: 01_045 | H34: Bread/rolls, white | J34: 0 | W34: 26 | X34: 1.2 | Y34: 0 | Z34: 1.2 | AC34: 0.8 | AD34: 28 | AE34: 0 | AF34: 0.18 | AG34: 0.06 | AH34: 0 | AI34: 0 | AJ34: 0 | AK34: 0.04 | AL34: 0
A35: 1147.01 | B35: =VLOOKUP(A35,'Table 3.1'!$A$4:$D$186,4,FALSE) -> 3.8624752 | C35: Eggs | F35: WA_FCT | G35: 08_001 | H35: Egg, chicken, raw | I35: A2 | J35: 0 | W35: 56 | X35: 1.8 | Y35: 1.8 | Z35: 0 | AC35: 1.29 | AD35: 47 | AE35: 0 | AF35: 0.04 | AG35: 0.46 | AH35: 160 | AI35: 5 | AJ35: 160 | AK35: 0.17 | AL35: 0.9
A36: 1169.99 | B36: =VLOOKUP(A36,'Table 3.1'!$A$4:$D$186,4,FALSE) -> 3.7753671 | C36: Other fruits & nuts (specify) | F36: USDA_FCT | G36: 12635 | H36: Mixed nuts, dry, RSTD,W/pnuts, w/salt | J36: 0 | W36: 70 | X36: 3.7 | Y36: 0 | Z36: 3.7 | AC36: 3.8 | AD36: 50 | AE36: 0.4 | AF36: 0.2 | AG36: 0.2 | AH36: 0 | AI36: 3 | AJ36: 0 | AK36: 0.296 | AL36: 0
A37: 1125.06 | B37: =VLOOKUP(A37,'Table 3.1'!$A$4:$D$186,4,FALSE) -> 3.7568521 | C37: Sausages, other than polony | F37: WA_FCT | G37: 07_063 | H37: Sausage, wiener (beef, pork, chicken) canned | J37: 0 | W37: 10 | X37: 0.88 | Y37: 0.88 | Z37: 0 | AC37: 1.6 | AD37: 4 | AE37: 0 | AF37: 0.09 | AG37: 0.11 | AH37: 0 | AI37: 0 | AJ37: 0 | AK37: 0.12 | AL37: 1
A38: 1144.01 | B38: =VLOOKUP(A38,'Table 3.1'!$A$4:$D$186,4,FALSE) -> 3.751732 | C38: Clotted/ Cultured milk | F38: WA_FCT | G38: 10_003 | H38: Milk, Goat, Raw | I38: B2 | J38: 0 | W38: 142 | X38: 0.1 | Y38: 0.1 | Z38: 0 | AC38: 0.3 | AD38: 1 | AE38: 1.5 | AF38: 0.06 | AG38: 0.17 | AH38: 33 | AI38: 0 | AJ38: 33 | AK38: 0.04 | AL38: 0.1
A39: 1112.04 | B39: =VLOOKUP(A39,'Table 3.1'!$A$4:$D$186,4,FALSE) -> 3.7198099 | C39: Vetkoek | D39: 3257 | E39: Vetkoek, home-made (cake flour, water) | F39: WA_FCT | G39: 01_045 | H39: Bread/rolls, white | J39: 0 | W39: 26 | X39: 1.2 | Y39: 0 | Z39: 1.2 | AC39: 0.8 | AD39: 28 | AE39: 0 | AF39: 0.18 | AG39: 0.06 | AH39: 0 | AI39: 0 | AJ39: 0 | AK39: 0.04 | AL39: 0
A40: 1175.01 | B40: =VLOOKUP(A40,'Table 3.1'!$A$4:$D$186,4,FALSE) -> 3.4039269 | C40: Beans (dried) | F40: WA_FCT | G40: 03_022 | H40: Beans, white, dried | J40: 0 | W40: 74 | X40: 5.7 | Y40: 0 | Z40: 5.7 | AC40: 3.77 | AD40: 395 | AE40: 0 | AF40: 0.89 | AG40: 0.11 | AH40: 0 | AI40: 179 | AJ40: 15 | AK40: 0.51 | AL40: 0
...

Sheet Table 3.1
A1: 3.1 Consumption statistics for each food item at national level
C2: Average quantity as purchased (g/capita/day) | D2: Average edible quantity (g/capita/day) | E2: Average food consumption in monetary value (LCU/capita/day) | F2: Average dietary energy consumption (kcal/capita/day) | G2: Median dietary energy unit value (LCU/1000 kcal)
A3: COICOP Code | B3: Descriptions
A4: 1111.01 | B4: Rice | C4: 22.321716 | D4: 22.321716 | E4: 1.005985 | F4: 77.902789 | G4: 2.9681439
A5: 1111.02 | B5: Malt/ Mealie Rice | C5: 0.066044358 | D5: 0.066044358 | E5: 0.10766371 | F5: 0.25763904 | G5: 3.5976402
A6: 1112.01 | B6: Bread (white, brown, whole wheat, rye, maize, etc.) | C6: 168.44418 | D6: 168.44418 | E6: 3.2543853 | F6: 419.7629 | G6: 7.427807
A7: 1112.02 | B7: Brotchen | C7: 0.44808198 | D7: 0.44808199 | E7: 0.053668778 | F7: 1.1833845 | G7: 46.947528
A8: 1112.03 | B8: Biscuits, rusks | C8: 0.65390381 | D8: 0.65390381 | E8: 0.023167464 | F8: 1.7269599 | G8: 14.99432
A9: 1112.04 | B9: Vetkoek | C9: 3.7198099 | D9: 3.7198099 | E9: 0.027475477 | F9: 9.8240179 | G9: 2.5242963
A10: 1112.09 | B10: Traditional bread, ash bread, oshikwiila, oshima, omungome | C10: 3.9007853 | D10: 3.9007853 | E10: 0.038751578 | F10: 10.301974 | G10: 3.7864444
A11: 1113.01 | B11: Macaroni, spaghetti, noodles | C11: 15.198223 | D11: 15.198223 | E11: 0.28540918 | F11: 23.754823 | G11: 11.405969
A12: 1114.01 | B12: Cakes (all types) | C12: 1.4542407 | D12: 1.4542407 | E12: 0.10746032 | F12: 4.8789775 | G12: 22.783482
A13: 1114.02 | B13: Pies & pizzas | C13: 0.27176901 | D13: 0.27176901 | E13: 0.016326867 | F13: 1.3673514 | G13: 11.954987
A14: 1115.01 | B14: Breakfast cereals (all types) | C14: 10.421325 | D14: 10.421325 | E14: 0.30050158 | F14: 3.9121654 | G14: 124.25265
A15: 1115.02 | B15: Baby foods, cereals | C15: 0.30590962 | D15: 0.30590962 | E15: 0.017081529 | F15: 1.4441993 | G15: 18.523617
... A157: 1191.08 | B157: Salad dressings | C157: 0.35499797 | D157: 0.35499796 | E157: 0.015168101 | F157: 1.4192818 | G157: 11.118654
A158: 1192.01 | B158: Salt | C158: 1.3220155 | D158: 1.3220155 | E158: 0.13749176 | F158: 0
A159: 1192.02 | B159: Spices & condiments | C159: 0.20638098 | D159: 0.20638098 | E159: 0.047430603 | F159: 0.71717392 | G159: 102.77492
A160: 1192.03 | B160: Garlic | C160: 0.015546423 | D160: 0.015526212 | E160: 0.0016942973 | F160: 0.020960387 | G160: 77.337325
A161: 1192.04 | B161: Ginger | C161: 0.00065216263 | D161: 0.00065131476 | E161: 6.4822873e-05 | F161: 0.00087927496 | G161: 73.723093
A162: 1193.02 | B162: Yeast | C162: 0.013373149 | D162: 0.013373149 | E162: 0.0040273985 | F162: 0.042112047 | G162: 127.02444
A163: 1193.04 | B163: Cake essences | C163: 0.00076794174 | D163: 0.00076794174 | E163: 6.7850062e-05 | F163: 0.0029829929 | G163: 41.512202
A164: 1193.05 | B164: Custards, puddings, jelly & gelatine | C164: 0.095242871 | D164: 0.095242871 | E164: 0.003545624 | F164: 0.31643492 | G164: 9.4279237
A165: 1193.06 | B165: Ready-made soup | C165: 0.21918641 | D165: 0.21918641 | E165: 0.0082760202 | F165: 0.13238859 | G165: 14.472282
A166: 1193.07 | B166: Powdered soup | C166: 1.1691881 | D166: 1.1691881 | E166: 0.14997037 | F166: 3.1715397 | G166: 60.582343
A167: 1194.01 | B167: Ready-made frozen food | C167: 0.10373333 | D167: 0.10373333 | E167: 0.0035647207 | F167: 0.062654931 | G167: 130.17321
A168: 1195.99 | B168: Other foods (specify) | C168: 8.955633 | D168: 8.9556331 | E168: 0.17686835 | F168: 5.4092024 | G168: 31.4571
A169: 1211.01 | B169: Coffee | C169: 0.77437576 | D169: 0.77437576 | E169: 0.081532309 | F169: 2.7443877 | G169: 67.18263
A170: 1212.01 | B170: Tea | C170: 20.632187 | D170: 20.632186 | E170: 0.10521724 | F170: 0.16505749 | G170: 312.5
... A172: 1219.99 | B172: Other infusions (specify) | C172: 0.7783891 | D172: 0.7783891 | E172: 0.033826748 | F172: 0.0062271128 | G172: 9326.9911
A173: 1221.01 | B173: Mineral water & ice cubes blocks | C173: 2.3823974 | D173: 2.3823974 | E173: 0.021712335 | F173: 0
A174: 1222.01 | B174: Soft drinks | C174: 20.18357 | D174: 20.183571 | E174: 0.28699572 | F174: 8.8000368 | G174: 31.968076
A175: 1222.99 | B175: Other non-alcoholic drinks (Energade, Powerade) (specify) | C175: 4.160192 | D175: 4.160192 | E175: 0.070147447 | F175: 1.8138437 | G175: 37.538763
A176: 1223.01 | B176: Fruit juice & squashes | C176: 13.384258 | D176: 13.384258 | E176: 0.27427086 | F176: 5.8355365 | G176: 45.584671
A177: 1223.02 | B177: Mageu/Oshikundu | C177: 112.25229 | D177: 112.25229 | E177: 0.41054207 | F177: 54.666866 | G177: 7.1658185
A178: 1223.99 | B178: Other powdered drinks (specify) | C178: 0.3731893 | D178: 0.37318929 | E178: 0.0087188164 | F178: 0.16271053 | G178: 58.853209
A179: 2111.04 | B179: Local home-made distilled drinks, all types (ombike, kashipembe) | C179: 0.28624203 | D179: 0.28624203 | E179: 0.029298003 | F179: 0.091597451 | G179: 156.25
A180: 2111.06 | B180: Whiskies | C180: 0.065044156 | D180: 0.065044156 | E180: 2.5977421 | F180: 223.48792 | G180: 10.327253
A181: 2121.01 | B181: Wines | C181: 0.59995743 | D181: 0.59995744 | E181: 0.036789315 | F181: 0.21478476 | G181: 130.35381
A182: 2122.01 | B182: Sparkling wines/ Champagnes | C182: 0.052912777 | D182: 0.052912778 | E182: 0.004426869 | F182: 0.018942774 | G182: 269.65857
...
