Workbook

Sheet FAO
B1: production (1000 tons) | C1: imports (1000 tons) | D1: exports (1000 tons) | E1: total (1000 tons) | F1: Percentage imported | G1: domestic supply (1000 tons) | H1: domestic supply (%) | I1: processing (1000 tons) | J1: food supply quantity (kg/capita/yr) | K1: food supply quantity (g/c/d)
A2: 2013
A3: Wheat and products | K3: 99.35
A4: Rice (milled equivalent) | K4: 17.29
A5: Barley and products | K5: 0
A6: Maize and products | K6: 118.93
A7: Millet and products | K7: 40.29
A8: Sorghum and products | K8: 6.66
A9: Total | K9: =SUM(K3:K8) -> 282.52
A11: 2014
A12: Wheat and products | B12: 10 | C12: 118 | D12: 5 | E12: =(B12+C12)-D12 -> 123 | F12: =C12/E12 -> 0.95934959 | G12: 118 | H12: =G12/$G$18 -> 0.34402332 | J12: 40.19
A13: Rice (milled equivalent) | B13: 0 | C13: 21 | D13: 0 | E13: =(B13+C13)-D13 -> 21 | F13: =C13/E13 -> 1 | G13: 19 | H13: =G13/$G$18 -> 0.055393586 | J13: 7.86
A14: Barley and products | B14: 0 | C14: 27 | D14: 1 | E14: =(B14+C14)-D14 -> 26 | F14: =C14/E14 -> 1.0384615 | H14: =G14/$G$18 -> 0 | I14: 39
A15: Maize and products | B15: 56 | C15: 106 | D15: 6 | E15: =(B15+C15)-D15 -> 156 | F15: =C15/E15 -> 0.67948718 | G15: 158 | H15: =G15/$G$18 -> 0.4606414 | J15: 44.05
A16: Millet and products | B16: 37 | C16: 4 | D16: 0 | E16: =(B16+C16)-D16 -> 41 | F16: =C16/E16 -> 0.097560976 | G16: 41 | H16: =G16/$G$18 -> 0.11953353 | J16: 15.38
A17: Sorghum and products | B17: 9 | C17: 0 | D17: 0 | E17: =(B17+C17)-D17 -> 9 | F17: =C17/E17 -> 0 | G17: 7 | H17: =G17/$G$18 -> 0.020408163 | I17: 1 | J17: 2.34
A18: Total | B18: =SUM(B12:B17) -> 112 | E18: =SUM(E12:E17) -> 376 | G18: =SUM(G12:G17) -> 343 | J18: =SUM(J12:J17) -> 109.82
A20: 2015
A21: Wheat and products | B21: 12 | C21: 131 | D21: 12 | E21: =(B21+C21)-D21 -> 131 | F21: =C21/E21 -> 1 | G21: 105 | H21: =G21/$G$27 -> 0.26315789 | J21: 42.6
A22: Rice (milled equivalent) | B22: 0 | C22: 26 | D22: 0 | E22: =(B22+C22)-D22 -> 26 | F22: =C22/E22 -> 1 | G22: 20 | H22: =G22/$G$27 -> 0.050125313 | J22: 8.33
A23: Barley and products | B23: 0 | C23: 42 | D23: 15 | E23: =(B23+C23)-D23 -> 27 | F23: =C23/E23 -> 1.5555556 | G23: 27 | H23: =G23/$G$27 -> 0.067669173 | I23: 39
A24: Maize and products | B24: 60 | C24: 144 | D24: 1 | E24: =(B24+C24)-D24 -> 203 | F24: =C24/E24 -> 0.70935961 | G24: 193 | H24: =G24/$G$27 -> 0.48370927 | J24: 46.05
A25: Millet and products | B25: 46 | C25: 5 | E25: =(B25+C25)-D25 -> 51 | F25: =C25/E25 -> 0.098039216 | G25: 48 | H25: =G25/$G$27 -> 0.12030075 | J25: 17.25
A26: Sorghum and products | B26: 7 | C26: 0 | D26: 0 | E26: =(B26+C26)-D26 -> 7 | F26: =C26/E26 -> 0 | G26: 6 | H26: =G26/$G$27 -> 0.015037594 | I26: 1 | J26: 1.99
A27: Total | B27: =SUM(B21:B26) -> 125 | E27: =SUM(E21:E26) -> 445 | G27: =SUM(G21:G26) -> 399 | J27: =SUM(J21:J26) -> 116.22
A29: 2016
A30: Wheat and products | B30: 14 | C30: 135 | D30: 8 | E30: =(B30+C30)-D30 -> 141 | F30: =C30/E30 -> 0.95744681 | G30: 146 | H30: =G30/$G$36 -> 0.30932203 | J30: 44.02
A31: Rice (milled equivalent) | B31: 0 | C31: 26 | D31: 0 | E31: =(B31+C31)-D31 -> 26 | F31: =C31/E31 -> 1 | G31: 20 | H31: =G31/$G$36 -> 0.042372881 | J31: 8.24
A32: Barley and products | B32: 0 | C32: 36 | D32: 5 | E32: =(B32+C32)-D32 -> 31 | F32: =C32/E32 -> 1.1612903 | G32: 30 | H32: =G32/$G$36 -> 0.063559322 | I32: 42
A33: Maize and products | B33: 64 | C33: 165 | D33: 2 | E33: =(B33+C33)-D33 -> 227 | F33: =C33/E33 -> 0.72687225 | G33: 223 | H33: =G33/$G$36 -> 0.47245763 | J33: 50.78
A34: Millet and products | B34: 46 | C34: 5 | E34: =(B34+C34)-D34 -> 51 | F34: =C34/E34 -> 0.098039216 | G34: 47 | H34: =G34/$G$36 -> 0.099576271 | J34: 16.34
A35: Sorghum and products | B35: 6 | C35: 0 | D35: 0 | E35: =(B35+C35)-D35 -> 6 | F35: =C35/E35 -> 0 | G35: 6 | H35: =G35/$G$36 -> 0.012711864 | I35: 1 | J35: 1.9
A36: Total | B36: =SUM(B30:B35) -> 130 | E36: =SUM(E30:E35) -> 482 | G36: =SUM(G30:G35) -> 472 | J36: =SUM(J30:J35) -> 121.28
A38: 2017
A39: Wheat and products | B39: 13 | C39: 135 | D39: 6 | E39: =(B39+C39)-D39 -> 142 | F39: =C39/E39 -> 0.95070423 | G39: 141 | H39: =G39/$G$45 -> 0.33975904 | J39: 42.42
A40: Rice (milled equivalent) | B40: 0 | C40: 30 | D40: 0 | E40: =(B40+C40)-D40 -> 30 | F40: =C40/E40 -> 1 | G40: 20 | H40: =G40/$G$45 -> 0.048192771 | J40: 8.08
A41: Barley and products | B41: 0 | C41: 37 | D41: 7 | E41: =(B41+C41)-D41 -> 30 | F41: =C41/E41 -> 1.2333333 | G41: 30 | H41: =G41/$G$45 -> 0.072289157 | I41: 42
A42: Maize and products | B42: 63 | C42: 88 | D42: 0 | E42: =(B42+C42)-D42 -> 151 | F42: =C42/E42 -> 0.58278146 | G42: 173 | H42: =G42/$G$45 -> 0.41686747 | J42: 44
A43: Millet and products | B43: 44 | C43: 4 | D43: 0 | E43: =(B43+C43)-D43 -> 48 | F43: =C43/E43 -> 0.083333333 | G43: 45 | H43: =G43/$G$45 -> 0.10843373 | J43: 15.43
A44: Sorghum and products | B44: 6 | C44: 0 | D44: 0 | E44: =(B44+C44)-D44 -> 6 | F44: =C44/E44 -> 0 | G44: 6 | H44: =G44/$G$45 -> 0.014457831 | I44: 1 | J44: 1.82
...

Sheet NEWFIU
A3: Requirements | E3: Total Cereals
A4: 2013/14 | E4: 260000
A5: 2014/15 | E5: 272000
A7: Availability | B7: Maize | C7: Millet/Mahangu and Sorghum | D7: Wheat | E7: Total
A8: 2013/14 | B8: 132000 | C8: 68000 | D8: 65000 | E8: =SUM(B8:D8) -> 265000 | F8: NEWFIU
B9: =B8/E8 -> 0.49811321 | C9: =C8/E8 -> 0.25660377 | D9: =D8/E8 -> 0.24528302
A10: 2014 | B10: =FAO!E15 -> 156 | C10: =FAO!E16+FAO!E17 -> 50 | D10: =FAO!E12 -> 123 | E10: =SUM(B10:D10) -> 329 | F10: FAO | G10: Why is NEWFIU so different esp for wheat?
B11: =B10/E10 -> 0.47416413 | C11: =C10/E10 -> 0.15197568 | D11: =D10/E10 -> 0.37386018

Sheet NAB commercial
A1: Tons | L1: NAB | M1: FAO
B2: 2010/11 | C2: 2011/12 | D2: 2012/13 | E2: 2013/14 | F2: 2014/15 | G2: 2015/16 | H2: 2016/17 | I2: 2017/18 | J2: 2018/19 | K2: Average | L2: Average 2014-2017 | M2: Average 2014-2017
A3: White Maize
A4: imports | B4: 81111 | C4: 55305 | D4: 105742 | E4: 170234 | F4: 82527 | G4: 120650 | H4: 110229 | I4: 50483 | J4: 59608 | K4: =AVERAGE(B4:J4) -> 92876.556 | L4: =AVERAGE(F4:I4) -> 90972.25 | M4: =FAO!C51*1000 -> 125750
A5: production marketed | B5: 47961 | C5: 63228 | D5: 72438 | E5: 36694 | F5: 69433 | G5: 38900 | H5: 43940 | I5: 76660 | J5: 58020 | K5: =AVERAGE(B5:J5) -> 56363.778 | L5: =AVERAGE(F5:I5) -> 57233.25 | M5: =(FAO!B51*1000) -> 60750
A6: total | B6: =SUM(B4:B5) -> 129072 | C6: =SUM(C4:C5) -> 118533 | D6: =SUM(D4:D5) -> 178180 | E6: =SUM(E4:E5) -> 206928 | F6: =SUM(F4:F5) -> 151960 | G6: =SUM(G4:G5) -> 159550 | H6: =SUM(H4:H5) -> 154169 | I6: =SUM(I4:I5) -> 127143 | J6: =SUM(J4:J5) -> 117628 | K6: =AVERAGE(B6:J6) -> 149240.33 | L6: =AVERAGE(F6:I6) -> 148205.5 | M6: =SUM(M4:M5) -> 186500
A7: % of imports | B7: =B4/B6 -> 0.6284167 | C7: =C4/C6 -> 0.46657893 | D7: =D4/D6 -> 0.59345606 | E7: =E4/E6 -> 0.82267262 | F7: =F4/F6 -> 0.54308371 | G7: =G4/G6 -> 0.75618928 | H7: =H4/H6 -> 0.7149881 | I7: =I4/I6 -> 0.39705686 | ... M7: =M4/M6 -> 0.67426273
A9: Wheat
A10: imports | B10: 65519 | C10: 84543 | D10: 87726 | E10: 85257 | F10: 103035 | G10: 95190 | H10: 121261 | I10: 104261 | J10: 118698 | K10: =AVERAGE(B10:J10) -> 96165.556 | L10: =AVERAGE(F10:I10) -> 105936.75 | M10: =(FAO!C48*1000) -> 129750
A11: production marketed | B11: 10038 | C11: 11930 | D11: 14819 | E11: 11312 | F11: 11600 | G11: 11411 | H11: 9822 | I11: 6863 | J11: 7508 | K11: =AVERAGE(B11:J11) -> 10589.222 | L11: =AVERAGE(F11:I11) -> 9924 | M11: =(FAO!B48*1000) -> 12250
A12: total | B12: =SUM(B10:B11) -> 75557 | C12: =SUM(C10:C11) -> 96473 | D12: =SUM(D10:D11) -> 102545 | E12: =SUM(E10:E11) -> 96569 | F12: =SUM(F10:F11) -> 114635 | G12: =SUM(G10:G11) -> 106601 | H12: =SUM(H10:H11) -> 131083 | I12: =SUM(I10:I11) -> 111124 | J12: =SUM(J10:J11) -> 126206 | K12: =AVERAGE(B12:J12) -> 106754.78 | L12: =AVERAGE(F12:I12) -> 115860.75 | M12: =SUM(M10:M11) -> 142000
A13: % of imports | B13: =B10/B12 -> 0.86714666 | C13: =C10/C12 -> 0.87633846 | D13: =D10/D12 -> 0.85548783 | E13: =E10/E12 -> 0.88286096 | F13: =F10/F12 -> 0.89880926 | G13: =G10/G12 -> 0.89295598 | H13: =H10/H12 -> 0.92507038 | I13: =I10/I12 -> 0.93824016 | ... M13: =M10/M12 -> 0.91373239
A15: Mahangu
A16: imports | B16: 1034 | C16: 1860 | D16: 3863 | E16: 5485 | F16: 3332 | G16: 6096 | H16: 5541 | I16: 3469 | J16: 931 | K16: =AVERAGE(B16:J16) -> 3512.3333 | L16: =AVERAGE(F16:I16) -> 4609.5 | M16: =(FAO!C52*1000) -> 4500
A17: production marketed | B17: 1064 | C17: 975 | D17: 1040 | E17: 532 | F17: 750 | G17: 111 | H17: 1584 | I17: 2344 | J17: 1979 | K17: =AVERAGE(B17:J17) -> 1153.2222 | L17: =AVERAGE(F17:I17) -> 1197.25 | M17: =(FAO!B52*1000) -> 43250 | O17: FAO and NAB very different for Mahungu domestic production
A18: total | B18: =SUM(B16:B17) -> 2098 | C18: =SUM(C16:C17) -> 2835 | D18: =SUM(D16:D17) -> 4903 | E18: =SUM(E16:E17) -> 6017 | F18: =SUM(F16:F17) -> 4082 | G18: =SUM(G16:G17) -> 6207 | H18: =SUM(H16:H17) -> 7125 | I18: =SUM(I16:I17) -> 5813 | J18: =SUM(J16:J17) -> 2910 | K18: =AVERAGE(B18:J18) -> 4665.5556 | L18: =AVERAGE(F18:I18) -> 5806.75 | M18: =SUM(M16:M17) -> 47750
A19: % of imports | B19: =B16/B18 -> 0.49285033 | C19: =C16/C18 -> 0.65608466 | D19: =D16/D18 -> 0.78788497 | E19: =E16/E18 -> 0.91158385 | F19: =F16/F18 -> 0.81626654 | G19: =G16/G18 -> 0.98211696 | H19: =H16/H18 -> 0.77768421 | I19: =I16/I18 -> 0.59676587 | ... M19: =M16/M18 -> 0.094240838
A21: imports | B21: 1034 | C21: 1860 | D21: 3863 | E21: 5485 | F21: 3332 | G21: 6096 | H21: 5541 | I21: 3469 | J21: 931 | K21: =AVERAGE(B21:J21) -> 3512.3333 | L21: =AVERAGE(F21:I21) -> 4609.5 | M21: =(FAO!C56*1000) -> 0
A22: estimated production | B22: 41166 | C22: 55921 | D22: 24695 | E22: 44141 | F22: 15302 | G22: 19428 | H22: 57644 | I22: 83515 | J22: 9277 | K22: =AVERAGE(B22:J22) -> 39009.889 | L22: =AVERAGE(F22:I22) -> 43972.25
A23: total | B23: =SUM(B21:B22) -> 42200 | C23: =SUM(C21:C22) -> 57781 | D23: =SUM(D21:D22) -> 28558 | E23: =SUM(E21:E22) -> 49626 | F23: =SUM(F21:F22) -> 18634 | G23: =SUM(G21:G22) -> 25524 | H23: =SUM(H21:H22) -> 63185 | I23: =SUM(I21:I22) -> 86984 | ... M23: =SUM(M21:M22) -> 0
A24: % of imports | B24: =B21/B23 -> 0.02450237 | C24: =C21/C23 -> 0.032190512 | D24: =D21/D23 -> 0.13526858 | E24: =E21/E23 -> 0.11052674 | F24: =F21/F23 -> 0.17881292 | G24: =G21/G23 -> 0.23883404 | H24: =H21/H23 -> 0.087694864 | I24: =I21/I23 -> 0.039880898 | ... M24: =M21/M23 -> #DIV/0!
A26: Total all (mahangu estimated production) | B26: =B6+B12+B23 -> 246829 | C26: =C6+C12+C23 -> 272787 | D26: =D6+D12+D23 -> 309283 | E26: =E6+E12+E23 -> 353123 | F26: =F6+F12+F23 -> 285229 | G26: =G6+G12+G23 -> 291675 | H26: =H6+H12+H23 -> 348437 | I26: =I6+I12+I23 -> 325251 | ... L26: =L6+L12+L23 -> 312648
A27: % Mahangu | B27: =B23/B26 -> 0.17096857 | C27: =C23/C26 -> 0.21181728 | D27: =D23/D26 -> 0.092336145 | E27: =E23/E26 -> 0.1405346 | F27: =F23/F26 -> 0.065329963 | G27: =G23/G26 -> 0.087508357 | H27: =H23/H26 -> 0.18133838 | I27: =I23/I26 -> 0.26743653 | ... L27: =L23/L26 -> 0.15538801 | M27: =M18/M26 -> #VALUE!
A28: % mahangu domestically produced | K28: =K22/K26 -> 0.13067881
A30: Total domestic production | B30: =B5+B11+B22 -> 99165 | C30: =C5+C11+C22 -> 131079 | D30: =D5+D11+D22 -> 111952 | E30: =E5+E11+E22 -> 92147 | F30: =F5+F11+F22 -> 96335 | G30: =G5+G11+G22 -> 69739 | H30: =H5+H11+H22 -> 111406 | I30: =I5+I11+I22 -> 167038 | ... K30: =K5+K11+K22 -> 105962.89
A31: % Mahangu | B31: =B22/B30 -> 0.4151263 | C31: =C22/C30 -> 0.42662059 | D31: =D22/D30 -> 0.22058561 | E31: =E22/E30 -> 0.47902807 | F31: =F22/F30 -> 0.15884154 | G31: =G22/G30 -> 0.27858157 | H31: =H22/H30 -> 0.51742276 | I31: =I22/I30 -> 0.49997605 | ... K31: =K22/K30 -> 0.36814671
A34: Source: https://www.nab.com.na/agronomy/agronomy-statistics/#1585672377295-6a63b89c-ea10
A35: Source: Mahangu estimated production: page 38 NAB Annual report 2018/2019 (Source: Crop Prospect and Food Security Situation Report, MAWF)
A37: NB.
A38: White maize: | B38: NAB annual report (page 24) indicates total volumne marketed in 2018/2019 as 56,422 (42%) of which 23,823 (58%) was rain fed and 32,599 was irrigated. Above figures indicate total marketed as 58,020
B39: NAB annual report (page 29) figures for maize irrigated production are not the same as on page 24
A41: Mahangu: | B41: NAB annual report (page 38) Data for "estimated production" is equal to MAWF data on communal production
A43: Commercial | B43: Commercial farmers sell all that is produced so production marketed is same as amount produced

Sheet MAWF original
G17: Commercial areas
G45: Zambezi
G72: Kavango East and West regions
G99: Omusati region
G127: Ohangwena region
G154: Oshana region
G181: Oshikoto region

Sheet MAWF communal
A1: Tons
B2: 2010/11 | C2: 2011/12 | D2: 2012/13 | E2: 2013/14 | F2: 2014/15 | G2: 2015/16 | H2: 2016/17 | I2: 2017/18 | J2: 2018/19 | K2: 2019/20 | L2: Average | N2: Population* | O2: Households* | P2: HH Size* | Q2: Household (%) produced [crop] in the last 12 monthsƚ | R2: Nƚ | S2: Amount of [crop] the household produced in the last 12 months (mean)ƚ | T2: Amount of [crop] the household consumed from own production in the past 12 monthsƚ | U2: Amount of [crop] the household gave away from own production in the past 12 monthsƚ | V2: Amount of [crop] the household sold from own production in the past 12 monthsƚ | W2: Amount of [crop] the household UNACCOUNTED from own production in the past 12 monthsƚ | X2: Est. TOTAL [crop] production | Y2: Est. EXCESS [crop] production
A3: White maize
A4: Zambezi | B4: 3888 | C4: 3538 | D4: 2123 | E4: 4458 | F4: 1293 | G4: 1021 | H4: 5983 | I4: 6521 | J4: 1274 | K4: 8350 | L4: =AVERAGE(B4:K4) -> 3844.9 | N4: 98849 | O4: 26901 | P4: 3.6745474 | Q4: 27.7 | R4: 566 | S4: 505.43547 | T4: 145.41615 | U4: 16.308264 | V4: 85.359433 | W4: 258.35162 | X4: =(O4*(Q4/100)*S4)/1000 -> 3766.2913 | Y4: =(O4*(Q4/100)*SUM(U4:W4))/1000 -> 2682.7117
A5: Kavango East and West | B5: 1354 | C5: 1016 | D5: 335 | E5: 774 | F5: 139 | G5: 185 | H5: 290 | I5: 365 | J5: 47 | K5: 184 | L5: =AVERAGE(B5:K5) -> 468.9 | N5: 237779 | O5: 52894 | P5: 4.495387 | Q5: 26.074153 | R5: 1122 | S5: 276.28688 | T5: 208.82474 | U5: 33.756933 | V5: 5.3918256 | W5: 28.313383 | X5: =(O5*(Q5/100)*S5)/1000 -> 3810.4555 | Y5: =(O5*(Q5/100)*SUM(U5:W5))/1000 -> 930.4151
A6: Omusati | B6: 0 | C6: 0 | D6: 0 | E6: 0 | F6: 0 | G6: 0 | H6: 0 | I6: 0 | J6: 0 | K6: 0 | L6: =AVERAGE(B6:K6) -> 0 | N6: 249885 | O6: 54383 | P6: 4.5949102 | Q6: 8.4 | R6: 854 | S6: 566.68109 | T6: 39.481722 | U6: 0.49466634 | V6: 485.8283 | W6: 40.876402 | X6: =(O6*(Q6/100)*S6)/1000 -> 2588.6967 | Y6: =(O6*(Q6/100)*SUM(U6:W6))/1000 -> 2408.3374
A7: Ohangwena | B7: 0 | C7: 0 | D7: 0 | E7: 0 | F7: 0 | G7: 0 | H7: 0 | I7: 0 | J7: 0 | K7: 0 | L7: =AVERAGE(B7:K7) -> 0 | N7: 255510 | O7: 49470 | P7: 5.1649485 | Q7: 11.4 | R7: 854 | S7: 23.242941 | T7: 18.311149 | U7: 1.1976981 | V7: 0 | W7: 3.7340937 | X7: =(O7*(Q7/100)*S7)/1000 -> 131.08042 | Y7: =(O7*(Q7/100)*SUM(U7:W7))/1000 -> 27.813234
A8: Oshana | B8: 0 | C8: 0 | D8: 0 | E8: 0 | F8: 0 | G8: 0 | H8: 0 | I8: 0 | J8: 0 | K8: 0 | L8: =AVERAGE(B8:K8) -> 0 | N8: 189237 | O8: 44544 | P8: 4.2483163 | Q8: 4.2 | R8: 846 | S8: 54.954049 | T8: 51.315298 | U8: 0.77908757 | V8: 0.10215231 | W8: 2.7575115 | X8: =(O8*(Q8/100)*S8)/1000 -> 102.81067 | Y8: =(O8*(Q8/100)*SUM(U8:W8))/1000 -> 6.8075508
A9: Oshikoto | B9: 0 | C9: 0 | D9: 0 | E9: 0 | F9: 0 | G9: 0 | H9: 0 | I9: 0 | J9: 0 | K9: 0 | L9: =AVERAGE(B9:K9) -> 0 | N9: 195165 | O9: 45407 | P9: 4.2981258 | Q9: 7 | R9: 837 | S9: 78.661735 | T9: 45.119648 | U9: 5.8415591 | V9: 11.770712 | W9: 15.929816 | X9: =(O9*(Q9/100)*S9)/1000 -> 250.02554 | Y9: =(O9*(Q9/100)*SUM(U9:W9))/1000 -> 106.61319
A10: 7 communal regions total | B10: =SUM(B4:B9) -> 5242 | C10: =SUM(C4:C9) -> 4554 | D10: =SUM(D4:D9) -> 2458 | E10: =SUM(E4:E9) -> 5232 | F10: =SUM(F4:F9) -> 1432 | G10: =SUM(G4:G9) -> 1206 | H10: =SUM(H4:H9) -> 6273 | I10: =SUM(I4:I9) -> 6886 | ... K10: =SUM(K4:K9) -> 8534 | L10: =AVERAGE(B10:K10) -> 4313.8 | N10: 1226425 | O10: 273599 | P10: 4.4825639 | X10: =SUM(X4:X9) -> 10649.36 | Y10: =SUM(Y4:Y9) -> 6162.6981
A11: Communal total | B11: 5242 | C11: 4554 | D11: 2458 | E11: 5232 | F11: 1432 | G11: 1206 | H11: 6273 | I11: 6886 | J11: 1321 | K11: 8534 | L11: =AVERAGE(B11:K11) -> 4313.8
A12: Pearl millet
A13: Zambezi | B13: 862 | C13: 810 | D13: 543 | E13: 1227 | F13: 331 | G13: 328 | H13: 459 | I13: 546 | J13: 153 | K13: 1469 | L13: =AVERAGE(B13:K13) -> 672.8 | N13: 98849 | O13: 26901 | P13: 3.6745474 | Q13: 4 | R13: 566 | S13: 99.639415 | T13: 67.901805 | U13: 9.2635683 | V13: 21.910587 | W13: 0.56345484 | X13: =(O13*(Q13/100)*S13)/1000 -> 107.216 | Y13: =(O13*(Q13/100)*SUM(U13:W13))/1000 -> 34.150939
A14: Kavango East and West | B14: 3631 | C14: 2469 | D14: 1358 | E14: 2825 | F14: 763 | G14: 1541 | H14: 3745 | I14: 6704 | J14: 1743 | K14: 8471 | L14: =AVERAGE(B14:K14) -> 3325 | N14: 237779 | O14: 52894 | P14: 4.495387 | Q14: 37.985918 | R14: 1122 | S14: 430.29676 | T14: 337.56263 | U14: 30.922455 | V14: 19.640031 | W14: 42.171642 | X14: =(O14*(Q14/100)*S14)/1000 -> 8645.6394 | Y14: =(O14*(Q14/100)*SUM(U14:W14))/1000 -> 1863.2393
A15: Omusati | B15: 10089 | C15: 11300 | D15: 3051 | E15: 7139 | F15: 3213 | G15: 4627 | H15: 12724 | I15: 21249 | J15: 1062 | K15: 20741 | L15: =AVERAGE(B15:K15) -> 9519.5 | N15: 249885 | O15: 54383 | P15: 4.5949102 | Q15: 59 | R15: 854 | S15: 453.54908 | T15: 263.77293 | U15: 14.607962 | V15: 15.470739 | W15: 159.69745 | X15: =(O15*(Q15/100)*S15)/1000 -> 14552.562 | Y15: =(O15*(Q15/100)*SUM(U15:W15))/1000 -> 6089.1518
A16: Ohangwena | B16: 6724 | C16: 10758 | D16: 4518 | E16: 6641 | F16: 2258 | G16: 3952 | H16: 11461 | I16: 15472 | J16: 2476 | K16: 18450 | L16: =AVERAGE(B16:K16) -> 8271 | N16: 255510 | O16: 49470 | P16: 5.1649485 | Q16: 66.6 | R16: 854 | S16: 375.10659 | T16: 229.23917 | U16: 11.556067 | V16: 1.5721078 | W16: 132.73925 | X16: =(O16*(Q16/100)*S16)/1000 -> 12358.644 | Y16: =(O16*(Q16/100)*SUM(U16:W16))/1000 -> 4805.8969
A17: Oshana | B17: 4110 | C17: 11423 | D17: 4112 | E17: 8306 | F17: 3156 | G17: 2115 | H17: 9623 | I17: 15397 | J17: 462 | K17: 14530 | L17: =AVERAGE(B17:K17) -> 7323.4 | N17: 189237 | O17: 44544 | P17: 4.2483163 | Q17: 38.9 | R17: 846 | S17: 293.74861 | T17: 183.43803 | U17: 4.6187731 | V17: 7.2543299 | W17: 98.437469 | X17: =(O17*(Q17/100)*S17)/1000 -> 5089.9631 | Y17: =(O17*(Q17/100)*SUM(U17:W17))/1000 -> 1911.4192
A18: Oshikoto | B18: 15706 | C18: 19161 | D18: 11113 | E18: 18003 | F18: 5581 | G18: 6865 | H18: 19632 | I18: 24147 | J18: 3381 | K18: 27168 | L18: =AVERAGE(B18:K18) -> 15075.7 | N18: 195165 | O18: 45407 | P18: 4.2981258 | Q18: 51.9 | R18: 837 | S18: 280.50395 | T18: 169.23103 | U18: 13.653099 | V18: 6.7986036 | W18: 90.821213 | X18: =(O18*(Q18/100)*S18)/1000 -> 6610.4213 | Y18: =(O18*(Q18/100)*SUM(U18:W18))/1000 -> 2622.2835
A19: 7 communal regions total | B19: =SUM(B13:B18) -> 41122 | C19: =SUM(C13:C18) -> 55921 | D19: =SUM(D13:D18) -> 24695 | E19: =SUM(E13:E18) -> 44141 | F19: =SUM(F13:F18) -> 15302 | G19: =SUM(G13:G18) -> 19428 | H19: =SUM(H13:H18) -> 57644 | I19: =SUM(I13:I18) -> 83515 | ... L19: =SUM(L13:L18) -> 44187.4 | N19: 1226425 | O19: 273599 | P19: 4.4825639 | X19: =SUM(X13:X18) -> 47364.446 | Y19: =SUM(Y13:Y18) -> 17326.142
A20: Communal total | B20: 41122 | C20: 55921 | D20: 24695 | E20: 44141 | F20: 15302 | G20: 19428 | H20: 57644 | I20: 83515 | J20: 9277 | K20: 90829 | L20: =AVERAGE(B20:K20) -> 44187.4
A21: Sorghum
A22: Zambezi | B22: 988 | C22: 1294 | D22: 867 | E22: 1864 | F22: 876 | G22: 718 | H22: 976 | I22: 869 | J22: 261 | K22: 1372 | L22: =AVERAGE(B22:K22) -> 1008.5 | N22: 98849 | O22: 26901 | P22: 3.6745474 | Q22: 2 | R22: 566 | S22: 78.453285 | T22: 64.944926 | U22: 4.2683888 | V22: 0.046199855 | W22: 9.1937712 | X22: =(O22*(Q22/100)*S22)/1000 -> 42.209437 | Y22: =(O22*(Q22/100)*SUM(U22:W22))/1000 -> 7.2677678
A23: Kavango East and West | B23: 568 | C23: 466 | D23: 126 | E23: 218 | F23: 87 | G23: 117 | H23: 184 | I23: 232 | J23: 44 | K23: 89 | L23: =AVERAGE(B23:K23) -> 213.1 | N23: 237779 | O23: 52894 | P23: 4.495387 | Q23: 5.4486631 | R23: 1122 | S23: 149.69329 | T23: 122.84014 | U23: 10.046769 | V23: 3.9344177 | W23: 12.871959 | X23: =(O23*(Q23/100)*S23)/1000 -> 431.41843 | Y23: =(O23*(Q23/100)*SUM(U23:W23))/1000 -> 77.391194
A24: Omusati | B24: 1030 | C24: 1318 | D24: 145 | E24: 271 | F24: 92 | G24: 107 | H24: 250 | I24: 438 | J24: 9 | K24: 1310 | L24: =AVERAGE(B24:K24) -> 497 | N24: 249885 | O24: 54383 | P24: 4.5949102 | Q24: 25.5 | R24: 854 | S24: 79.312183 | T24: 55.041706 | U24: 2.4677998 | V24: 0 | W24: 21.802677 | X24: =(O24*(Q24/100)*S24)/1000 -> 1099.8748 | Y24: =(O24*(Q24/100)*SUM(U24:W24))/1000 -> 336.57484
A25: Ohangwena | B25: 1310 | C25: 1507 | D25: 377 | E25: 664 | F25: 292 | G25: 273 | H25: 603 | I25: 1206 | J25: 48 | K25: 1350 | L25: =AVERAGE(B25:K25) -> 763 | N25: 255510 | O25: 49470 | P25: 5.1649485 | Q25: 25.3 | R25: 854 | S25: 29.856127 | T25: 23.57729 | U25: 0.25167841 | V25: 0.57434512 | W25: 5.4528134 | X25: =(O25*(Q25/100)*S25)/1000 -> 373.67659 | Y25: =(O25*(Q25/100)*SUM(U25:W25))/1000 -> 78.585358
A26: Oshana | B26: 917 | C26: 2127 | D26: 277 | E26: 573 | F26: 138 | G26: 108 | H26: 324 | I26: 629 | J26: 6 | K26: 1850 | L26: =AVERAGE(B26:K26) -> 694.9 | N26: 189237 | O26: 44544 | P26: 4.2483163 | Q26: 11.2 | R26: 846 | S26: 70.458371 | T26: 31.993472 | U26: 7.1453587 | V26: 4.0768056 | W26: 27.242734 | X26: =(O26*(Q26/100)*S26)/1000 -> 351.51174 | Y26: =(O26*(Q26/100)*SUM(U26:W26))/1000 -> 191.89861
A27: Oshikoto | B27: 956 | C27: 1023 | D27: 399 | E27: 563 | F27: 186 | G27: 184 | H27: 447 | I27: 662 | J27: 20 | K27: 1135 | L27: =AVERAGE(B27:K27) -> 557.5 | N27: 195165 | O27: 45407 | P27: 4.2981258 | Q27: 8.7 | R27: 837 | S27: 63.423754 | T27: 45.794387 | U27: 4.1672368 | V27: 3.4801949 | W27: 9.981935 | X27: =(O27*(Q27/100)*S27)/1000 -> 250.54977 | Y27: =(O27*(Q27/100)*SUM(U27:W27))/1000 -> 69.643209
A28: 7 communal regions total | B28: =SUM(B22:B27) -> 5769 | C28: =SUM(C22:C27) -> 7735 | D28: =SUM(D22:D27) -> 2191 | E28: =SUM(E22:E27) -> 4153 | F28: =SUM(F22:F27) -> 1671 | G28: =SUM(G22:G27) -> 1507 | H28: =SUM(H22:H27) -> 2784 | I28: =SUM(I22:I27) -> 4036 | ... K28: =SUM(K22:K27) -> 7106 | L28: =AVERAGE(B28:K28) -> 3734 | N28: 1226425 | O28: 273599 | P28: 4.4825639 | X28: =SUM(X22:X27) -> 2549.2408 | Y28: =SUM(Y22:Y27) -> 761.36098
A29: Communal total | B29: 5769 | C29: 7735 | D29: 2191 | E29: 4153 | F29: 1671 | G29: 1507 | H29: 2784 | I29: 4036 | J29: 388 | K29: 7106 | L29: =AVERAGE(B29:K29) -> 3734
A30: Wheat
A31: No communal wheat
A33: Source: cereal production data sent by Matheus Ndjodhi, MAWF on 29 June 2020; (i) data on national commercial production and 7 communal regions, and (i) national production for maize commercial and communal, millet, sorghum and wheat. | N33: * Namibia Inter-censal Demographic Survey, 2016 Report
N34: ƚ Analysis of 2015/16 Namibia Hosehold Income and Expenditure Survey
A35: Communal: grow for own consumption and then sell suprplus, amount marketd is not the same as amount produced. These figures are "amount produced"

Sheet Total cereal availability
B1: Tons
C2: 2010/11 | D2: 2011/12 | E2: 2012/13 | F2: 2013/14 | G2: 2014/15 | H2: 2015/16 | I2: 2016/17 | J2: 2017/18 | K2: 2018/19 | L2: 2019/20 | M2: Average (2010/11-2018/19)
A4: Source | B4: White Maize
A5: NAB | B5: imports | C5: 81111 | D5: 55305 | E5: 105742 | F5: 170234 | G5: 82527 | H5: 120650 | I5: 110229 | J5: 50483 | K5: 59608 | M5: =AVERAGE(C5:K5) -> 92876.556
A6: NAB | B6: commercial production marketed | C6: 47961 | D6: 63228 | E6: 72438 | F6: 36694 | G6: 69433 | H6: 38900 | I6: 43940 | J6: 76660 | K6: 58020 | M6: =AVERAGE(C6:K6) -> 56363.778
A7: MAWF | B7: communal | C7: 5242 | D7: 4554 | E7: 2458 | F7: 5232 | G7: 1432 | H7: 1206 | I7: 6273 | J7: 6886 | K7: 1321 | L7: 8534 | M7: =AVERAGE(C7:L7) -> 4313.8
B8: Total white maize | C8: =SUM(C5:C7) -> 134314 | D8: =SUM(D5:D7) -> 123087 | E8: =SUM(E5:E7) -> 180638 | F8: =SUM(F5:F7) -> 212160 | G8: =SUM(G5:G7) -> 153392 | H8: =SUM(H5:H7) -> 160756 | I8: =SUM(I5:I7) -> 160442 | J8: =SUM(J5:J7) -> 134029 | ... M8: =SUM(M5:M7) -> 153554.13
B9: % communal | C9: =C7/C8 -> 0.039027949 | D9: =D7/D8 -> 0.036998221 | E9: =E7/E8 -> 0.013607325 | F9: =F7/F8 -> 0.024660633 | G9: =G7/G8 -> 0.0093355586 | H9: =H7/H8 -> 0.0075020528 | I9: =I7/I8 -> 0.039098241 | J9: =J7/J8 -> 0.051376941 | ... M9: =M7/M8 -> 0.028093024
B11: Wheat
A12: NAB | B12: imports | C12: 65519 | D12: 84543 | E12: 87726 | F12: 85257 | G12: 103035 | H12: 95190 | I12: 121261 | J12: 104261 | K12: 118698 | M12: =AVERAGE(C12:K12) -> 96165.556
A13: NAB | B13: commercial production marketed | C13: 10038 | D13: 11930 | E13: 14819 | F13: 11312 | G13: 11600 | H13: 11411 | I13: 9822 | J13: 6863 | K13: 7508 | M13: =AVERAGE(C13:K13) -> 10589.222
A14: MAWF | B14: communal | C14: 0 | D14: 0 | E14: 0 | F14: 0 | G14: 0 | H14: 0 | I14: 0 | J14: 0 | K14: 0
B15: Total wheat | C15: =SUM(C12:C14) -> 75557 | D15: =SUM(D12:D14) -> 96473 | E15: =SUM(E12:E14) -> 102545 | F15: =SUM(F12:F14) -> 96569 | G15: =SUM(G12:G14) -> 114635 | H15: =SUM(H12:H14) -> 106601 | I15: =SUM(I12:I14) -> 131083 | J15: =SUM(J12:J14) -> 111124 | ... M15: =SUM(M12:M14) -> 106754.78
B17: Mahangu
A18: NAB | B18: imports | C18: 1034 | D18: 1860 | E18: 3863 | F18: 5485 | G18: 3332 | H18: 6096 | I18: 5541 | J18: 3469 | K18: 931 | M18: =AVERAGE(C18:K18) -> 3512.3333
A19: NAB | B19: commercial production | C19: 0 | D19: 0 | E19: 0 | F19: 0 | G19: 0 | H19: 0 | I19: 0 | J19: 0 | K19: 0 | M19: =AVERAGE(C19:K19) -> 0
A20: MAWF | B20: communal | C20: 41122 | D20: 55921 | E20: 24695 | F20: 44141 | G20: 15302 | H20: 19428 | I20: 57644 | J20: 83515 | K20: 9277 | L20: 90829 | M20: =AVERAGE(C20:L20) -> 44187.4
B21: Total mahangu | C21: =SUM(C18:C20) -> 42156 | D21: =SUM(D18:D20) -> 57781 | E21: =SUM(E18:E20) -> 28558 | F21: =SUM(F18:F20) -> 49626 | G21: =SUM(G18:G20) -> 18634 | H21: =SUM(H18:H20) -> 25524 | I21: =SUM(I18:I20) -> 63185 | J21: =SUM(J18:J20) -> 86984 | ... M21: =SUM(M18:M20) -> 47699.733
B22: % communal | C22: =C20/C21 -> 0.97547206 | D22: =D20/D21 -> 0.96780949 | E22: =E20/E21 -> 0.86473142 | F22: =F20/F21 -> 0.88947326 | G22: =G20/G21 -> 0.82118708 | H22: =H20/H21 -> 0.76116596 | I22: =I20/I21 -> 0.91230514 | J22: =J20/J21 -> 0.9601191 | ... M22: =M20/M21 -> 0.92636577
B24: Sorghum
A25: NAB | B25: imports
A26: NAB | B26: production marketed
A27: MAWF | B27: communal | C27: 5769 | D27: 7735 | E27: 2191 | F27: 4153 | G27: 1671 | H27: 1507 | I27: 2784 | J27: 4036 | K27: 388 | L27: 7106 | M27: =AVERAGE(C27:L27) -> 3734
B28: Total sorghum | C28: =SUM(C25:C27) -> 5769 | D28: =SUM(D25:D27) -> 7735 | E28: =SUM(E25:E27) -> 2191 | F28: =SUM(F25:F27) -> 4153 | G28: =SUM(G25:G27) -> 1671 | H28: =SUM(H25:H27) -> 1507 | I28: =SUM(I25:I27) -> 2784 | J28: =SUM(J25:J27) -> 4036 | ... M28: =SUM(M25:M27) -> 3734
B29: % communal | C29: =C27/C28 -> 1 | D29: =D27/D28 -> 1 | E29: =E27/E28 -> 1 | F29: =F27/F28 -> 1 | G29: =G27/G28 -> 1 | H29: =H27/H28 -> 1 | I29: =I27/I28 -> 1 | J29: =J27/J28 -> 1 | ... M29: =M27/M28 -> 1
B31: Total all | C31: =C8+C15+C21+C28 -> 257796 | D31: =D8+D15+D21+D28 -> 285076 | E31: =E8+E15+E21+E28 -> 313932 | F31: =F8+F15+F21+F28 -> 362508 | G31: =G8+G15+G21+G28 -> 288332 | H31: =H8+H15+H21+H28 -> 294388 | I31: =I8+I15+I21+I28 -> 357494 | J31: =J8+J15+J21+J28 -> 336173 | ... M31: =M8+M15+M21+M28 -> 311742.64
B32: % imported and commercial wheat and maize | C32: =(C5+C6+C12+C13)/C31 -> 0.79376329 | D32: =(D5+D6+D12+D13)/D31 -> 0.7542059 | E32: =(E5+E6+E12+E13)/E31 -> 0.89422232 | F32: =(F5+F6+F12+F13)/F31 -> 0.83721463 | G32: =(G5+G6+G12+G13)/G31 -> 0.92461121 | H32: =(H5+H6+H12+H13)/H31 -> 0.90408237 | I32: =(I5+I6+I12+I13)/I31 -> 0.79792108 | J32: =(J5+J6+J12+J13)/J31 -> 0.70876305 | ... M32: =(M5+M6+M12+M13)/M31 -> 0.8211745
B33: % imported wheat and maize | C33: =(C5+C12)/C31 -> 0.56878307 | D33: =(D5+D12)/D31 -> 0.49056392 | E33: =(E5+E12)/E31 -> 0.61627359 | F33: =(F5+F12)/F31 -> 0.7047872 | G33: =(G5+G12)/G31 -> 0.64357061 | H33: =(H5+H12)/H31 -> 0.73318206 | I33: =(I5+I12)/I31 -> 0.64753534 | J33: =(J5+J12)/J31 -> 0.46031061 | ... M33: =(M5+M12)/M31 -> 0.6064044
A35: Sources: | B35: NAB imports: | C35: https://www.nab.com.na/agronomy/agronomy-statistics/#1585672377295-6a63b89c-ea10
B36: NAB production marketed | C36: https://www.nab.com.na/agronomy/agronomy-statistics/#1585672377295-6a63b89c-ea10
B37: MAWF communal | C37: cereal production data sent by Matheus Ndjodhi, MAWF on 29 June 2020; (i) 7 communal regions, and (i) national summary
A39: NB. | B39: Communal white maize is only grown in Zambezi and East and West Kavango
B41: Get regional commercial data to see if there are regions with significantly greater proportion of communal mahangu and sorghum
B43: Average total
B44: imports maize | C44: 92876.556
B45: commercial maize | C45: 56363.778
B46: communal maize | C46: 4313.8
B47: imports wheat | C47: 96165.556
B48: commercial wheat | C48: 10589.222
B49: imports mahangu | C49: 3512.3333
...
