Workbook

Sheet OPTION 1 - Working Tab
A1: OPTION 1 - Daily intake estimates - compared with RNI, EAR, UL iodine - Input data according to the national situation. | G1: Data inputs required ONLY in light blue shaded cells. Other data will automatically update. | L1: Text in brown font = instruction
A2: Click on dark grey shaded cells for instructions on information to insert in the corresponding light blue cell | G2: Exception to above is for light green shading for salt iodine standard. This is autofilled, but can be overwritten where a different standard applies
A3: Where data are available for different groups, copy this sheet together with the associated (working) charts , label and complete for: population age/sex group; geographic areas; different socio-economic (SES) groups.
A4: CHARTS in following sheets will update automatically when data are entered below. See EXPLAIN sheet for more information on adapting the charts | O4: Use non-pregnant adult ref values
A5: Population group | B5: Non-pregnant adult | E5: Minimum | F5: Maximum | G5: Mean | J5: Pregnant women | K5: Lactating women | L5: Non-pregnant adult | M5: Children 6-12 years | N5: Children 0-5 years | O5: Not specified
A6: Estimated Average Requirement iodine (EAR) (µg) | B6: =_xlfn.IFS($B$5=$J$5,J6, $B$5=$K$5,K6, $B$5=$L$5,L6, $B$5=$M$5,M6, $B$5=$N$5,N6, $B$5=$O$5,O6) -> 95 | D6: National salt iodine standards (mg/kg or µg/g) | E6: 50 | F6: 80 | G6: =IF(AND(E6>0,F6>0),(E6+F6)/2, E6) -> 65 | I6: EAR iodine (µg) | J6: 160 | K6: N/A | L6: 95 | M6: 65 | N6: 65 | O6: 95
A7: Recommended daily iodine intake (RNI) (µg) | B7: =_xlfn.IFS($B$5=$J$5,J7, $B$5=$K$5,K7, $B$5=$L$5,L7, $B$5=$M$5,M7, $B$5=$N$5,N7, $B$5=$O$5,O7) -> 150 | I7: RNI iodine (µg) Also known as RDA | J7: 250 | K7: 250 | L7: 150 | M7: 120 | N7: 90 | O7: 150
A8: Tolerable upper limit iodine (UL) | B8: =_xlfn.IFS($B$5=$J$5,J8, $B$5=$K$5,K8, $B$5=$L$5,L8, $B$5=$M$5,M8, $B$5=$N$5,N8, $B$5=$O$5,O8) -> 600 | I8: UL iodine (µg) | J8: 600 | K8: 600 | L8: 600 | M8: 300 | N8: N/A | O8: 600
A10: Additional description of data shown in each table | I10: EAR iodine | J10: Estimated Average Requirement
A11: Geographic area (define) | B11: National | I11: RNI (RDA) iodine | J11: Recommended Nutrient Intake
A12: SES group (define) | I12: UL iodine (µg) | J12: Tolerable upper limit for iodine intake
A14: Add sheet rows and change formulae in TOTAL row where more food types are required | G14: Main Outcome: If all food grade salt is iodised at mean mg/kg of the national salt iodine standard (adjusted for imports as needed), and assuming 30% loss of iodine | K14: Optional - estimated current iodine intake: If data on current household and food industry use of iodised salt known Based on estimated current % salt iodised with assumed mean (mg/kg) national salt iodine standard (adjusted for imports as needed) and 30% iodine loss | P14: Optional - iodine intake if salt reduction (SR) achieved with variable SR targets by food type, if known. Based on potential iodine intake if all food grade salt iodised (O) and on iodine intake with estimated current % salt iodised (P).
A15: Column label: | C15: A | D15: B | E15: C | F15: D | G15: E | H15: F | I15: G | J15: H | K15: I | L15: J | M15: K | N15: L | O15: M | P15: N | Q15: O | R15: P
A16: Food product (aim for at least 4 products). Include household (HH) salt where possible | B16: Source reference code | C16: Estimated average daily per capita consumption (g) | D16: Salt content (% product weight) | E16: Estimated daily salt intake from the product (g) | F16: Salt iodine standard (mg/kg or µg/g) Overwrite the autofill where different standard applies, e.g. for imported foods | G16: Potential iodine intake (µg) from daily intake (g) of the product | H16: Potential % EAR for iodine from typical daily intake of the product | I16: Potential % RNI for iodine from typical daily intake of the product | J16: Potential % UL for iodine from typical daily intake of the product | K16: Estimated percent of total salt used in the product that is iodised | L16: Estimated current iodine intake (µg) from daily intake of the product (g) | M16: Estimated current % EAR for iodine from typical daily intake of the product | N16: Estimated current % RNI for iodine from typical daily intake of the product | O16: Estimated current % UL for iodine from typical daily intake of the product | P16: Target reduction in salt content of the product (%) | Q16: Potential iodine intake (µg) from daily intake of the product (g) based on ALL salt iodised and after SR | R16: Estimated iodine intake (µg) from daily intake of the product (g) based on estimated current levels iodisation and after SR
A17: Calculation for each column: | E17: A * B | G17: C * D * 70% (for losses) | H17: E / EAR iodine for population group | I17: E / RNI iodine for population group | J17: E / UL iodine for population group | L17: E * I | M17: J / EAR iodine for population group | N17: J / RNI iodine for population group | O17: J / UL iodine for population group | Q17: E * N | R17: J * N
A18: Food type | G18: Potential iodine intake (µg) | H18: Potential % EAR iodine | I18: Potential % RNI iodine | J18: Potential % UL iodine | L18: Estimated current iodine intake (µg) | M18: Current % EAR iodine | N18: Current % RNI iodine | O18: Current % UL iodine | Q18: Potential iodine intake (µg) after SR | R18: Estimated current iodine intake (µg) after SR
A19: Household salt | C19: 1.3 | D19: 1 | E19: =C19*D19 -> 1.3 | F19: =$G$6 -> 65 | G19: =E19*F19*0.7 -> 59.15 | H19: =G19/$B$6 -> 0.62263158 | I19: =G19/$B$7 -> 0.39433333 | J19: =G19/$B$8 -> 0.098583333 | K19: 0.76 | L19: =G19*K19 -> 44.954 | M19: =L19/$B$6 -> 0.4732 | N19: =L19/$B$7 -> 0.29969333 | O19: =L19/$B$8 -> 0.074923333 | P19: 0.05 | Q19: =G19*(1-P19) -> 56.1925 | R19: =L19*(1-P19) -> 42.7063
A20: Bread & brotchen | C20: =168.44+0.5 -> 168.94 | D20: 0.016 | E20: =C20*D20 -> 2.70304 | F20: =$G$6 -> 65 | G20: =E20*F20*0.7 -> 122.98832 | H20: =G20/$B$6 -> 1.2946139 | I20: =G20/$B$7 -> 0.81992213 | J20: =G20/$B$8 -> 0.20498053 | K20: 1 | L20: =G20*K20 -> 122.98832 | M20: =L20/$B$6 -> 1.2946139 | N20: =L20/$B$7 -> 0.81992213 | O20: =L20/$B$8 -> 0.20498053 | P20: 0.15 | Q20: =G20*(1-P20) -> 104.54007 | R20: =L20*(1-P20) -> 104.54007
A21: Dried fish | C21: 2.7 | D21: 0.139 | E21: =C21*D21 -> 0.3753 | F21: =$G$6 -> 65 | G21: =E21*F21*0.7 -> 17.07615 | H21: =G21/$B$6 -> 0.17974895 | I21: =G21/$B$7 -> 0.113841 | J21: =G21/$B$8 -> 0.02846025 | K21: 1 | L21: =G21*K21 -> 17.07615 | M21: =L21/$B$6 -> 0.17974895 | N21: =L21/$B$7 -> 0.113841 | O21: =L21/$B$8 -> 0.02846025 | P21: 0.03 | Q21: =G21*(1-P21) -> 16.563866 | R21: =L21*(1-P21) -> 16.563866
A22: Powdered soup | C22: 1.2 | D22: 0.15 | E22: =C22*D22 -> 0.18 | F22: =$G$6 -> 65 | G22: =E22*F22*0.7 -> 8.19 | H22: =G22/$B$6 -> 0.086210526 | I22: =G22/$B$7 -> 0.0546 | J22: =G22/$B$8 -> 0.01365 | K22: 1 | L22: =G22*K22 -> 8.19 | M22: =L22/$B$6 -> 0.086210526 | N22: =L22/$B$7 -> 0.0546 | O22: =L22/$B$8 -> 0.01365 | P22: 0.15 | Q22: =G22*(1-P22) -> 6.9615 | R22: =L22*(1-P22) -> 6.9615
A23: Sausages, other than polony | C23: 3.8 | D23: 0.032 | E23: =C23*D23 -> 0.1216 | F23: =$G$6 -> 65 | G23: =E23*F23*0.7 -> 5.5328 | H23: =G23/$B$6 -> 0.05824 | I23: =G23/$B$7 -> 0.036885333 | J23: =G23/$B$8 -> 0.0092213333 | K23: 1 | L23: =G23*K23 -> 5.5328 | M23: =L23/$B$6 -> 0.05824 | N23: =L23/$B$7 -> 0.036885333 | O23: =L23/$B$8 -> 0.0092213333 | P23: 0 | Q23: =G23*(1-P23) -> 5.5328 | R23: =L23*(1-P23) -> 5.5328
A24: Spices & condiments | C24: 0.2 | D24: 0.3 | E24: =C24*D24 -> 0.06 | F24: =$G$6 -> 65 | G24: =E24*F24*0.7 -> 2.73 | H24: =G24/$B$6 -> 0.028736842 | I24: =G24/$B$7 -> 0.0182 | J24: =G24/$B$8 -> 0.00455 | K24: 1 | L24: =G24*K24 -> 2.73 | M24: =L24/$B$6 -> 0.028736842 | N24: =L24/$B$7 -> 0.0182 | O24: =L24/$B$8 -> 0.00455 | P24: 0.1 | Q24: =G24*(1-P24) -> 2.457 | R24: =L24*(1-P24) -> 2.457
A25: Traditional bread | C25: 3.9 | D25: 0.016 | E25: =C25*D25 -> 0.0624 | F25: =$G$6 -> 65 | G25: =E25*F25*0.7 -> 2.8392 | H25: =G25/$B$6 -> 0.029886316 | I25: =G25/$B$7 -> 0.018928 | J25: =G25/$B$8 -> 0.004732 | K25: 1 | L25: =G25*K25 -> 2.8392 | M25: =L25/$B$6 -> 0.029886316 | N25: =L25/$B$7 -> 0.018928 | O25: =L25/$B$8 -> 0.004732 | P25: 0.05 | Q25: =G25*(1-P25) -> 2.69724 | R25: =L25*(1-P25) -> 2.69724
A26: Chips & crisps | C26: 2.4 | D26: 0.025 | E26: =C26*D26 -> 0.06 | F26: =$G$6 -> 65 | G26: =E26*F26*0.7 -> 2.73 | H26: =G26/$B$6 -> 0.028736842 | I26: =G26/$B$7 -> 0.0182 | J26: =G26/$B$8 -> 0.00455 | K26: 1 | L26: =G26*K26 -> 2.73 | M26: =L26/$B$6 -> 0.028736842 | N26: =L26/$B$7 -> 0.0182 | O26: =L26/$B$8 -> 0.00455 | Q26: =G26*(1-P26) -> 2.73 | R26: =L26*(1-P26) -> 2.73
A27: Smoked fish | C27: 1.9 | D27: 0.017 | E27: =C27*D27 -> 0.0323 | F27: =$G$6 -> 65 | G27: =E27*F27*0.7 -> 1.46965 | H27: =G27/$B$6 -> 0.01547 | I27: =G27/$B$7 -> 0.0097976667 | J27: =G27/$B$8 -> 0.0024494167 | K27: 1 | L27: =G27*K27 -> 1.46965 | M27: =L27/$B$6 -> 0.01547 | N27: =L27/$B$7 -> 0.0097976667 | O27: =L27/$B$8 -> 0.0024494167 | Q27: =G27*(1-P27) -> 1.46965 | R27: =L27*(1-P27) -> 1.46965
A28: Polony | C28: 1.2 | D28: 0.026 | E28: =C28*D28 -> 0.0312 | F28: =$G$6 -> 65 | G28: =E28*F28*0.7 -> 1.4196 | H28: =G28/$B$6 -> 0.014943158 | I28: =G28/$B$7 -> 0.009464 | J28: =G28/$B$8 -> 0.002366 | K28: 1 | L28: =G28*K28 -> 1.4196 | M28: =L28/$B$6 -> 0.014943158 | N28: =L28/$B$7 -> 0.009464 | O28: =L28/$B$8 -> 0.002366 | Q28: =G28*(1-P28) -> 1.4196 | R28: =L28*(1-P28) -> 1.4196
A29: Cheese, all types | C29: 1.1 | D29: 0.02 | E29: =C29*D29 -> 0.022 | F29: =$G$6 -> 65 | G29: =E29*F29*0.7 -> 1.001 | H29: =G29/$B$6 -> 0.010536842 | I29: =G29/$B$7 -> 0.0066733333 | J29: =G29/$B$8 -> 0.0016683333 | K29: 1 | L29: =G29*K29 -> 1.001 | M29: =L29/$B$6 -> 0.010536842 | N29: =L29/$B$7 -> 0.0066733333 | O29: =L29/$B$8 -> 0.0016683333 | Q29: =G29*(1-P29) -> 1.001 | R29: =L29*(1-P29) -> 1.001
A30: Canned meat | C30: 0.6 | D30: 0.025 | E30: =C30*D30 -> 0.015 | F30: =$G$6 -> 65 | G30: =E30*F30*0.7 -> 0.6825 | H30: =G30/$B$6 -> 0.0071842105 | I30: =G30/$B$7 -> 0.00455 | J30: =G30/$B$8 -> 0.0011375 | K30: 1 | L30: =G30*K30 -> 0.6825 | M30: =L30/$B$6 -> 0.0071842105 | N30: =L30/$B$7 -> 0.00455 | O30: =L30/$B$8 -> 0.0011375 | Q30: =G30*(1-P30) -> 0.6825 | R30: =L30*(1-P30) -> 0.6825
A31: Biltong | C31: 0.3 | D31: 0.053 | E31: =C31*D31 -> 0.0159 | F31: =$G$6 -> 65 | G31: =E31*F31*0.7 -> 0.72345 | H31: =G31/$B$6 -> 0.0076152632 | I31: =G31/$B$7 -> 0.004823 | J31: =G31/$B$8 -> 0.00120575 | K31: 1 | L31: =G31*K31 -> 0.72345 | M31: =L31/$B$6 -> 0.0076152632 | N31: =L31/$B$7 -> 0.004823 | O31: =L31/$B$8 -> 0.00120575 | Q31: =G31*(1-P31) -> 0.72345 | R31: =L31*(1-P31) -> 0.72345
A32: Smoked meat, other than bacon & ham | C32: 0.4 | D32: 0.024 | E32: =C32*D32 -> 0.0096 | F32: =$G$6 -> 65 | G32: =E32*F32*0.7 -> 0.4368 | H32: =G32/$B$6 -> 0.0045978947 | I32: =G32/$B$7 -> 0.002912 | J32: =G32/$B$8 -> 0.000728 | K32: 1 | L32: =G32*K32 -> 0.4368 | M32: =L32/$B$6 -> 0.0045978947 | N32: =L32/$B$7 -> 0.002912 | O32: =L32/$B$8 -> 0.000728 | Q32: =G32*(1-P32) -> 0.4368 | R32: =L32*(1-P32) -> 0.4368
A33: Tomato sauce | C33: 0.6 | D33: 0.014 | E33: =C33*D33 -> 0.0084 | F33: =$G$6 -> 65 | G33: =E33*F33*0.7 -> 0.3822 | H33: =G33/$B$6 -> 0.0040231579 | I33: =G33/$B$7 -> 0.002548 | J33: =G33/$B$8 -> 0.000637 | K33: 1 | L33: =G33*K33 -> 0.3822 | M33: =L33/$B$6 -> 0.0040231579 | N33: =L33/$B$7 -> 0.002548 | O33: =L33/$B$8 -> 0.000637 | Q33: =G33*(1-P33) -> 0.3822 | R33: =L33*(1-P33) -> 0.3822
A34: Bacon | C34: 0.2 | D34: 0.03 | E34: =C34*D34 -> 0.006 | F34: =$G$6 -> 65 | G34: =E34*F34*0.7 -> 0.273 | H34: =G34/$B$6 -> 0.0028736842 | I34: =G34/$B$7 -> 0.00182 | J34: =G34/$B$8 -> 0.000455 | K34: 1 | L34: =G34*K34 -> 0.273 | M34: =L34/$B$6 -> 0.0028736842 | N34: =L34/$B$7 -> 0.00182 | O34: =L34/$B$8 -> 0.000455 | Q34: =G34*(1-P34) -> 0.273 | R34: =L34*(1-P34) -> 0.273
A35: Ham | C35: 0.1 | D35: 0.033 | E35: =C35*D35 -> 0.0033 | F35: =$G$6 -> 65 | G35: =E35*F35*0.7 -> 0.15015 | H35: =G35/$B$6 -> 0.0015805263 | I35: =G35/$B$7 -> 0.001001 | J35: =G35/$B$8 -> 0.00025025 | K35: 1 | L35: =G35*K35 -> 0.15015 | M35: =L35/$B$6 -> 0.0015805263 | N35: =L35/$B$7 -> 0.001001 | O35: =L35/$B$8 -> 0.00025025 | Q35: =G35*(1-P35) -> 0.15015 | R35: =L35*(1-P35) -> 0.15015
A36: Pies & pizza | C36: 0.3 | D36: 0.01 | E36: =C36*D36 -> 0.003 | F36: =$G$6 -> 65 | G36: =E36*F36*0.7 -> 0.1365 | H36: =G36/$B$6 -> 0.0014368421 | I36: =G36/$B$7 -> 0.00091 | J36: =G36/$B$8 -> 0.0002275 | K36: 1 | L36: =G36*K36 -> 0.1365 | M36: =L36/$B$6 -> 0.0014368421 | N36: =L36/$B$7 -> 0.00091 | O36: =L36/$B$8 -> 0.0002275 | Q36: =G36*(1-P36) -> 0.1365 | R36: =L36*(1-P36) -> 0.1365
A37: Biscuits, rusks | C37: 0.7 | D37: 0.003 | E37: =C37*D37 -> 0.0021 | F37: =$G$6 -> 65 | G37: =E37*F37*0.7 -> 0.09555 | H37: =G37/$B$6 -> 0.0010057895 | I37: =G37/$B$7 -> 0.000637 | J37: =G37/$B$8 -> 0.00015925 | K37: 1 | L37: =G37*K37 -> 0.09555 | M37: =L37/$B$6 -> 0.0010057895 | N37: =L37/$B$7 -> 0.000637 | O37: =L37/$B$8 -> 0.00015925 | Q37: =G37*(1-P37) -> 0.09555 | R37: =L37*(1-P37) -> 0.09555
A38: Ready made soup | C38: 0.2 | D38: 0.009 | E38: =C38*D38 -> 0.0018 | F38: =$G$6 -> 65 | G38: =E38*F38*0.7 -> 0.0819 | H38: =G38/$B$6 -> 0.00086210526 | I38: =G38/$B$7 -> 0.000546 | J38: =G38/$B$8 -> 0.0001365 | K38: 1 | L38: =G38*K38 -> 0.0819 | M38: =L38/$B$6 -> 0.00086210526 | N38: =L38/$B$7 -> 0.000546 | O38: =L38/$B$8 -> 0.0001365 | Q38: =G38*(1-P38) -> 0.0819 | R38: =L38*(1-P38) -> 0.0819
A39: Food 21 | E39: =C39*D39 -> 0 | F39: =$G$6 -> 65 | G39: =E39*F39*0.7 -> 0 | H39: =G39/$B$6 -> 0 | I39: =G39/$B$7 -> 0 | J39: =G39/$B$8 -> 0 | L39: =G39*K39 -> 0 | M39: =L39/$B$6 -> 0 | N39: =L39/$B$7 -> 0 | O39: =L39/$B$8 -> 0 | Q39: =G39*(1-P39) -> 0 | R39: =L39*(1-P39) -> 0
A40: Food 22 | E40: =C40*D40 -> 0 | F40: =$G$6 -> 65 | G40: =E40*F40*0.7 -> 0 | H40: =G40/$B$6 -> 0 | I40: =G40/$B$7 -> 0 | J40: =G40/$B$8 -> 0 | L40: =G40*K40 -> 0 | M40: =L40/$B$6 -> 0 | N40: =L40/$B$7 -> 0 | O40: =L40/$B$8 -> 0 | Q40: =G40*(1-P40) -> 0 | R40: =L40*(1-P40) -> 0
A41: Food 23 | E41: =C41*D41 -> 0 | F41: =$G$6 -> 65 | G41: =E41*F41*0.7 -> 0 | H41: =G41/$B$6 -> 0 | I41: =G41/$B$7 -> 0 | J41: =G41/$B$8 -> 0 | L41: =G41*K41 -> 0 | M41: =L41/$B$6 -> 0 | N41: =L41/$B$7 -> 0 | O41: =L41/$B$8 -> 0 | Q41: =G41*(1-P41) -> 0 | R41: =L41*(1-P41) -> 0
A42: Food 24 | E42: =C42*D42 -> 0 | F42: =$G$6 -> 65 | G42: =E42*F42*0.7 -> 0 | H42: =G42/$B$6 -> 0 | I42: =G42/$B$7 -> 0 | J42: =G42/$B$8 -> 0 | L42: =G42*K42 -> 0 | M42: =L42/$B$6 -> 0 | N42: =L42/$B$7 -> 0 | O42: =L42/$B$8 -> 0 | Q42: =G42*(1-P42) -> 0 | R42: =L42*(1-P42) -> 0
...

Sheet OPTION 1 - Data for Figures
A1: Data to generate a chart showing estimated iodine intake from household (HH) salt compared with from processed food salt for the 3 different situations
A2: Household salt must be the first food in the "Food Type" list for the formulae and charts to work. Reorder the list - that is currently auto-inserted here from the previous sheet - as needed
A3: Please check all figures match those in previous sheet
A4: If this information doesn't transfer from the first sheet correctly, either re-do the formulae or overwrite the formulae and type in food types and figures for the columns separately.
C6: ='OPTION 1 - Working Tab'!G16 -> Potential iodine intake (µg) from daily intake (g) of the product | D6: ='OPTION 1 - Working Tab'!L16 -> Estimated current iodine intake (µg) from daily intake of the product (g) | E6: Potential iodine intake (µg) from daily intake of the product (g) based on ALL salt iodized and lower iodine level | F6: Potential iodine intake (µg) from daily intake of the product (g) based on estimated current levels of iodisation and lower iodine level
A7: ='OPTION 1 - Working Tab'!A18 -> Food type | C7: ='OPTION 1 - Working Tab'!G18 -> Potential iodine intake (µg) | D7: ='OPTION 1 - Working Tab'!L18 -> Estimated current iodine intake (µg) | E7: Potential iodine intake (µg) with lower iodine level | F7: Estimated iodine intake (µg) with lower iodine level
A8: ='OPTION 1 - Working Tab'!A19 -> Household salt | C8: ='OPTION 1 - Working Tab'!G19 -> 59.15 | D8: ='OPTION 1 - Working Tab'!L19 -> 44.954 | E8: 27.3 | F8: 20.748
A9: ='OPTION 1 - Working Tab'!A20 -> Bread & brotchen | C9: ='OPTION 1 - Working Tab'!G20 -> 122.98832 | D9: ='OPTION 1 - Working Tab'!L20 -> 122.98832 | E9: 56.76384 | F9: 56.76384
A10: ='OPTION 1 - Working Tab'!A21 -> Dried fish | C10: ='OPTION 1 - Working Tab'!G21 -> 17.07615 | D10: ='OPTION 1 - Working Tab'!L21 -> 17.07615 | E10: 7.8813 | F10: 7.8813
A11: ='OPTION 1 - Working Tab'!A22 -> Powdered soup | C11: ='OPTION 1 - Working Tab'!G22 -> 8.19 | D11: ='OPTION 1 - Working Tab'!L22 -> 8.19 | E11: 3.78 | F11: 3.78
A12: ='OPTION 1 - Working Tab'!A23 -> Sausages, other than polony | C12: ='OPTION 1 - Working Tab'!G23 -> 5.5328 | D12: ='OPTION 1 - Working Tab'!L23 -> 5.5328 | E12: 2.5536 | F12: 2.5536
A13: ='OPTION 1 - Working Tab'!A24 -> Spices & condiments | C13: ='OPTION 1 - Working Tab'!G24 -> 2.73 | D13: ='OPTION 1 - Working Tab'!L24 -> 2.73 | E13: 1.26 | F13: 1.26
A14: ='OPTION 1 - Working Tab'!A25 -> Traditional bread | C14: ='OPTION 1 - Working Tab'!G25 -> 2.8392 | D14: ='OPTION 1 - Working Tab'!L25 -> 2.8392 | E14: 1.3104 | F14: 1.3104
A15: ='OPTION 1 - Working Tab'!A26 -> Chips & crisps | C15: ='OPTION 1 - Working Tab'!G26 -> 2.73 | D15: ='OPTION 1 - Working Tab'!L26 -> 2.73 | E15: 1.26 | F15: 1.26
A16: ='OPTION 1 - Working Tab'!A27 -> Smoked fish | C16: ='OPTION 1 - Working Tab'!G27 -> 1.46965 | D16: ='OPTION 1 - Working Tab'!L27 -> 1.46965 | E16: 0.6783 | F16: 0.6783
A17: ='OPTION 1 - Working Tab'!A28 -> Polony | C17: ='OPTION 1 - Working Tab'!G28 -> 1.4196 | D17: ='OPTION 1 - Working Tab'!L28 -> 1.4196 | E17: 0.6552 | F17: 0.6552
A18: ='OPTION 1 - Working Tab'!A29 -> Cheese, all types | C18: ='OPTION 1 - Working Tab'!G29 -> 1.001 | D18: ='OPTION 1 - Working Tab'!L29 -> 1.001 | E18: 0.462 | F18: 0.462
A19: ='OPTION 1 - Working Tab'!A30 -> Canned meat | C19: ='OPTION 1 - Working Tab'!G30 -> 0.6825 | D19: ='OPTION 1 - Working Tab'!L30 -> 0.6825 | E19: 0.315 | F19: 0.315
... A27: ='OPTION 1 - Working Tab'!A38 -> Ready made soup | C27: ='OPTION 1 - Working Tab'!G38 -> 0.0819 | D27: ='OPTION 1 - Working Tab'!L38 -> 0.0819 | E27: 0.0378 | F27: 0.0378
A28: ='OPTION 1 - Working Tab'!A39 -> Food 21 | C28: ='OPTION 1 - Working Tab'!G39 -> 0 | D28: ='OPTION 1 - Working Tab'!L39 -> 0 | E28: ='OPTION 1 - Working Tab'!Q39 -> 0 | F28: ='OPTION 1 - Working Tab'!R39 -> 0
A29: ='OPTION 1 - Working Tab'!A40 -> Food 22 | C29: ='OPTION 1 - Working Tab'!G40 -> 0 | D29: ='OPTION 1 - Working Tab'!L40 -> 0 | E29: ='OPTION 1 - Working Tab'!Q40 -> 0 | F29: ='OPTION 1 - Working Tab'!R40 -> 0
A30: ='OPTION 1 - Working Tab'!A41 -> Food 23 | C30: ='OPTION 1 - Working Tab'!G41 -> 0 | D30: ='OPTION 1 - Working Tab'!L41 -> 0 | E30: ='OPTION 1 - Working Tab'!Q41 -> 0 | F30: ='OPTION 1 - Working Tab'!R41 -> 0
A31: ='OPTION 1 - Working Tab'!A42 -> Food 24 | C31: ='OPTION 1 - Working Tab'!G42 -> 0 | D31: ='OPTION 1 - Working Tab'!L42 -> 0 | E31: ='OPTION 1 - Working Tab'!Q42 -> 0 | F31: ='OPTION 1 - Working Tab'!R42 -> 0
A32: ='OPTION 1 - Working Tab'!A43 -> Food 25 | C32: ='OPTION 1 - Working Tab'!G43 -> 0 | D32: ='OPTION 1 - Working Tab'!L43 -> 0 | E32: ='OPTION 1 - Working Tab'!Q43 -> 0 | F32: ='OPTION 1 - Working Tab'!R43 -> 0
A33: For HH salt | C33: =C8 -> 59.15 | D33: =D8 -> 44.954 | E33: =E8 -> 27.3 | F33: =F8 -> 20.748
A34: For all seleccted processed foods excluding HH salt | C34: =SUM(C9:C32) -> 168.93877 | D34: =SUM(D9:D32) -> 168.93877 | E34: =SUM(E9:E32) -> 77.97174 | F34: =SUM(F9:F32) -> 77.97174
A35: Estimated Average Requirement (µg) | B35: ='OPTION 1 - Working Tab'!B6 -> 95 | C35: =+B35 -> 95 | D35: =+C35 -> 95 | E35: =+D35 -> 95 | F35: =+D35 -> 95 | G35: =+F35 -> 95
A36: Recommended Nutrient Intake (µg) | B36: ='OPTION 1 - Working Tab'!B7 -> 150 | C36: =+B36 -> 150 | D36: =+C36 -> 150 | E36: =+D36 -> 150 | F36: =+D36 -> 150 | G36: =+F36 -> 150

Sheet Lists
A5: Pregnant women
A6: Lactating women
A7: Non-pregnant adult
A8: Children 6-12 years
A9: Children 0-5 years
A10: Not specified
